Workbook

Sheet ListOption
A1: symbol | B1: last_price | C1: bid_price | D1: ask_price | E1: mark_price_live
A2: SOL-26JUN26-70-P-USDT | B2: 0.7 | C2: 0.63 | D2: 0.67 | E2: 0.6109535
A3: SOL-26JUN26-72-P-USDT | B3: 1.56 | C3: 0.85 | D3: 0.9 | E3: 0.84884646
A4: SOL-26JUN26-74-P-USDT | B4: 1.25 | C4: 1.16 | D4: 1.21 | E4: 1.1703566

Sheet OptionBoard
A1: symbol | B1: strike | C1: delta | D1: gamma | E1: vega | F1: theta | G1: mark_price | H1: iv | I1: dte | J1: T | K1: type | L1: spot_price | M1: hedge_cost_per_day | N1: open_interest
A2: SOL-12JUN26-60-P-USDT | B2: 60 | C2: -0.09762761 | D2: 0.01634276 | E2: 0.01884251 | F2: -0.10762038 | G2: 0.51653985 | H2: 0.9657 | I2: 8 | J2: 0.021917808 | K2: PUT | L2: 71.72 | M2: 0.064567481 | N2: 111
A3: SOL-12JUN26-62-P-USDT | B3: 62 | C3: -0.13199103 | D3: 0.02124147 | E3: 0.0233593 | F3: -0.12725583 | G3: 0.71085656 | H3: 0.9211 | I3: 8 | J3: 0.021917808 | K3: PUT | L3: 71.72 | M3: 0.08885707 | N3: 10
A4: SOL-12JUN26-64-P-USDT | B4: 64 | C4: -0.17725246 | D4: 0.02703299 | E4: 0.02839573 | F4: -0.14775922 | G4: 0.98082448 | H4: 0.8798 | I4: 8 | J4: 0.021917808 | K4: PUT | L4: 71.72 | M4: 0.12260306 | N4: 104
A5: SOL-12JUN26-66-P-USDT | B5: 66 | C5: -0.2354303 | D5: 0.03341661 | E5: 0.03361236 | F5: -0.16748589 | G5: 1.3539284 | H5: 0.8425 | I5: 8 | J5: 0.021917808 | K5: PUT | L5: 71.72 | M5: 0.16924106 | N5: 2162
A6: SOL-12JUN26-68-P-USDT | B6: 68 | C6: -0.3075575 | D6: 0.03972563 | E6: 0.03841604 | F6: -0.1840335 | G6: 1.8634843 | H6: 0.81 | I6: 8 | J6: 0.021917808 | K6: PUT | L6: 71.72 | M6: 0.23293553 | N6: 105
A7: SOL-12JUN26-70-P-USDT | B7: 70 | C7: -0.39257405 | D7: 0.04491861 | E7: 0.04200178 | F7: -0.1945591 | G7: 2.545212 | H7: 0.7832 | I7: 8 | J7: 0.021917808 | K7: PUT | L7: 71.72 | M7: 0.3181515 | N7: 1154
A8: SOL-12JUN26-72-P-USDT | B8: 72 | C8: -0.48639682 | D8: 0.04782202 | E8: 0.04356657 | F8: -0.19661715 | G8: 3.4298496 | H8: 0.7631 | I8: 8 | J8: 0.021917808 | K8: PUT | L8: 71.72 | M8: 0.4287312 | N8: 260
A9: SOL-12JUN26-74-P-USDT | B9: 74 | C9: -0.58211611 | D9: 0.04763922 | E9: 0.04266518 | F9: -0.18928883 | G9: 4.5332691 | H9: 0.7501 | I9: 8 | J9: 0.021917808 | K9: PUT | L9: 71.72 | M9: 0.56665863 | N9: 140
A10: SOL-12JUN26-75-P-USDT | B10: 75 | C10: -0.62819653 | D10: 0.04636835 | E10: 0.04132142 | F10: -0.1824195 | G10: 5.1660093 | H10: 0.7464 | I10: 8 | J10: 0.021917808 | K10: PUT | L10: 71.72 | M10: 0.64575116 | N10: 346
A11: SOL-12JUN26-76-P-USDT | B11: 76 | C11: -0.6718913 | D11: 0.04441771 | E11: 0.03948008 | F11: -0.17383708 | G11: 5.8493848 | H11: 0.7445 | I11: 8 | J11: 0.021917808 | K11: PUT | L11: 71.72 | M11: 0.7311731 | N11: 183
A12: SOL-12JUN26-68-C-USDT | B12: 68 | C12: 0.69244251 | D12: 0.03972563 | E12: 0.03841604 | F12: -0.1840335 | G12: 5.6634843 | H12: 0.81 | I12: 8 | J12: 0.021917808 | K12: CALL | L12: 71.72 | M12: 0.70793553 | N12: 0
A13: SOL-12JUN26-70-C-USDT | B13: 70 | C13: 0.60742596 | D13: 0.04491861 | E13: 0.04200178 | F13: -0.1945591 | G13: 4.345212 | H13: 0.7832 | I13: 8 | J13: 0.021917808 | K13: CALL | L13: 71.72 | M13: 0.5431515 | N13: 0
... A73: SOL-26JUN26-110-C-USDT | B73: 110 | C73: 0.01119287 | D73: 0.00227565 | E73: 0.00523075 | F73: -0.00845894 | G73: 0.04692859 | H73: 0.7263 | I73: 22 | J73: 0.060273973 | K73: CALL | L73: 71.72 | M73: 0.0021331177 | N73: 100

Sheet Actives
A2: Информация по базовому активу
A4: № | B4: Дата покупки | C4: Актив | D4: Количество | E4: Цена | F4: Нач. Стоимость | G4: Тек.стоимость | H4: Pnl
B5: 46114 | C5: Meteor | D5: =2.0423-D8 | E5: 80.5 | F5: =D5*E5 | G5: =D5*Portfolio!$C$4 | H5: =G5-F5
B6: 46113 | C6: Swap | D6: 1.8 | E6: 84.44 | F6: =D6*E6 | G6: =D6*Portfolio!$C$4 | H6: =G6-F6
B7: 46112 | C7: Swap | D7: 1.0007 | E7: 83.26 | F7: =D7*E7 | G7: =D7*Portfolio!$C$4 | H7: =G7-F7
B8: 46110 | C8: Swap | D8: 1.0019 | E8: 81.84 | F8: =D8*E8 | G8: =D8*Portfolio!$C$4 | H8: =G8-F8
B9: 46108 | C9: Swap | D9: 1.0004 | E9: 82.97 | F9: =D9*E9 | G9: =D9*Portfolio!$C$4 | H9: =G9-F9
B10: 46120 | C10: Swap | D10: 2 | E10: 84.6 | F10: =D10*E10 | G10: =D10*Portfolio!$C$4 | H10: =G10-F10
B11: 46172 | C11: Swap | D11: 2 | E11: 82 | F11: =D11*E11 | G11: =D11*Portfolio!$C$4 | H11: =G11-F11
B13: Total | D13: =SUM(D5:D12) | E13: =F13/D13 | F13: =SUM(F5:F12) | G13: =SUM(G5:G12) | H13: =SUM(H5:H12)
A18: № | B18: Дата операции | C18: Protocol | D18: Pnl
B19: 46114 | C19: Option | D19: -10
B20: 46114 | C20: Meteor | D20: 10.95
B21: 46114 | C21: Meteor | D21: 8.73
B22: 46114 | C22: Meteor | D22: 5.4
B23: 46094 | C23: Option | D23: -15
B24: 46093 | C24: Meteor | D24: 4.73
B25: 46115 | C25: Option | D25: 2.37
B26: 46117 | C26: Option | D26: -1.4
B27: 46118 | C27: Option | D27: -2.36
B28: 46118 | C28: Option | D28: -3.5
B29: 46119 | C29: Option | D29: -5.73
B30: 46119 | C30: Option | D30: -5.67
... B34: 46125 | C34: Option | D34: -1.56
D36: =SUM(D19:D35)

Sheet Hedge_Total
A1: symbol | B1: strike | C1: delta | D1: gamma | E1: vega | F1: theta | G1: mark_price | H1: iv | I1: dte | J1: T | K1: type | L1: spot_price | M1: hedge_cost_per_day | N1: total_price | O1: position | P1: contracts | R1: Start | S1: Current
A2: =Portfolio!H10 | B2: =VLOOKUP(A2,OptionBoard!$A$2:$M$86,2,FALSE()) | C2: =VLOOKUP(A2,OptionBoard!$A$2:$M$86,3,0) | D2: =VLOOKUP(A2,OptionBoard!$A$2:$M$86,4,0) | E2: =VLOOKUP(A2,OptionBoard!$A$2:$M$86,5,0) | F2: =VLOOKUP(A2,OptionBoard!$A$2:$M$86,6,0) | G2: =N2/P2 | H2: =VLOOKUP(A2,OptionBoard!$A$2:$M$86,8,0) | I2: =VLOOKUP(A2,OptionBoard!$A$2:$M$86,9,0) | J2: =VLOOKUP(A2,OptionBoard!$A$2:$M$86,10,0) | K2: =VLOOKUP(A2,OptionBoard!$A$2:$M$86,11,FALSE()) | L2: =VLOOKUP(A2,OptionBoard!$A$2:$M$86,12,0) | M2: =VLOOKUP(A2,OptionBoard!$A$2:$M$86,13,0) | N2: =Portfolio!J10 | O2: buy | P2: =Portfolio!I10 | R2: =G2 | S2: =VLOOKUP(A2,OptionBoard!$A$2:$G$93,7,FALSE()) | U2: =R2-S2
A3: =Portfolio!H11 | B3: =VLOOKUP(A3,OptionBoard!$A$2:$M$86,2,FALSE()) | C3: =VLOOKUP(A3,OptionBoard!$A$2:$M$86,3,0) | D3: =VLOOKUP(A3,OptionBoard!$A$2:$M$86,4,0) | E3: =VLOOKUP(A3,OptionBoard!$A$2:$M$86,5,0) | F3: =VLOOKUP(A3,OptionBoard!$A$2:$M$86,6,0) | G3: =N3/P3 | H3: =VLOOKUP(A3,OptionBoard!$A$2:$M$86,8,0) | I3: =VLOOKUP(A3,OptionBoard!$A$2:$M$86,9,0) | J3: =VLOOKUP(A3,OptionBoard!$A$2:$M$86,10,0) | K3: =VLOOKUP(A3,OptionBoard!$A$2:$M$86,11,FALSE()) | L3: =VLOOKUP(A3,OptionBoard!$A$2:$M$86,12,0) | M3: =VLOOKUP(A3,OptionBoard!$A$2:$M$86,13,0) | N3: =Portfolio!J11 | O3: buy | P3: =Portfolio!I11 | R3: =G3 | S3: =VLOOKUP(A3,OptionBoard!$A$2:$G$93,7,FALSE()) | U3: =R3-S3
A4: =Portfolio!H12 | B4: =VLOOKUP(A4,OptionBoard!$A$2:$M$86,2,FALSE()) | C4: =VLOOKUP(A4,OptionBoard!$A$2:$M$86,3,0) | D4: =VLOOKUP(A4,OptionBoard!$A$2:$M$86,4,0) | E4: =VLOOKUP(A4,OptionBoard!$A$2:$M$86,5,0) | F4: =VLOOKUP(A4,OptionBoard!$A$2:$M$86,6,0) | G4: =N4/P4 | H4: =VLOOKUP(A4,OptionBoard!$A$2:$M$86,8,0) | I4: =VLOOKUP(A4,OptionBoard!$A$2:$M$86,9,0) | J4: =VLOOKUP(A4,OptionBoard!$A$2:$M$86,10,0) | K4: =VLOOKUP(A4,OptionBoard!$A$2:$M$86,11,FALSE()) | L4: =VLOOKUP(A4,OptionBoard!$A$2:$M$86,12,0) | M4: =VLOOKUP(A4,OptionBoard!$A$2:$M$86,13,0) | N4: =Portfolio!J12 | O4: buy | P4: =Portfolio!I12 | R4: =G4 | S4: =VLOOKUP(A4,OptionBoard!$A$2:$G$93,7,FALSE()) | U4: =R4-S4
A5: =Portfolio!H13 | B5: =VLOOKUP(A5,OptionBoard!$A$2:$M$86,2,FALSE()) | C5: =VLOOKUP(A5,OptionBoard!$A$2:$M$86,3,0) | D5: =VLOOKUP(A5,OptionBoard!$A$2:$M$86,4,0) | E5: =VLOOKUP(A5,OptionBoard!$A$2:$M$86,5,0) | F5: =VLOOKUP(A5,OptionBoard!$A$2:$M$86,6,0) | G5: =N5/P5 | H5: =VLOOKUP(A5,OptionBoard!$A$2:$M$86,8,0) | I5: =VLOOKUP(A5,OptionBoard!$A$2:$M$86,9,0) | J5: =VLOOKUP(A5,OptionBoard!$A$2:$M$86,10,0) | K5: =VLOOKUP(A5,OptionBoard!$A$2:$M$86,11,FALSE()) | L5: =VLOOKUP(A5,OptionBoard!$A$2:$M$86,12,0) | M5: =VLOOKUP(A5,OptionBoard!$A$2:$M$86,13,0) | N5: =Portfolio!J13 | O5: buy | P5: =Portfolio!I13 | R5: =G5 | S5: =VLOOKUP(A5,OptionBoard!$A$2:$G$93,7,FALSE()) | U5: =R5-S5
A6: =Portfolio!H14 | B6: =VLOOKUP(A6,OptionBoard!$A$2:$M$86,2,FALSE()) | C6: =VLOOKUP(A6,OptionBoard!$A$2:$M$86,3,0) | D6: =VLOOKUP(A6,OptionBoard!$A$2:$M$86,4,0) | E6: =VLOOKUP(A6,OptionBoard!$A$2:$M$86,5,0) | F6: =VLOOKUP(A6,OptionBoard!$A$2:$M$86,6,0) | G6: =N6/P6 | H6: =VLOOKUP(A6,OptionBoard!$A$2:$M$86,8,0) | I6: =VLOOKUP(A6,OptionBoard!$A$2:$M$86,9,0) | J6: =VLOOKUP(A6,OptionBoard!$A$2:$M$86,10,0) | K6: =VLOOKUP(A6,OptionBoard!$A$2:$M$86,11,FALSE()) | L6: =VLOOKUP(A6,OptionBoard!$A$2:$M$86,12,0) | M6: =VLOOKUP(A6,OptionBoard!$A$2:$M$86,13,0) | N6: =Portfolio!J14 | O6: buy | P6: =Portfolio!I14 | R6: =G6 | S6: =VLOOKUP(A6,OptionBoard!$A$2:$G$93,7,FALSE()) | U6: =R6-S6
A7: =Portfolio!H15 | B7: =VLOOKUP(A7,OptionBoard!$A$2:$M$86,2,FALSE()) | C7: =VLOOKUP(A7,OptionBoard!$A$2:$M$86,3,0) | D7: =VLOOKUP(A7,OptionBoard!$A$2:$M$86,4,0) | E7: =VLOOKUP(A7,OptionBoard!$A$2:$M$86,5,0) | F7: =VLOOKUP(A7,OptionBoard!$A$2:$M$86,6,0) | G7: =N7/P7 | H7: =VLOOKUP(A7,OptionBoard!$A$2:$M$86,8,0) | I7: =VLOOKUP(A7,OptionBoard!$A$2:$M$86,9,0) | J7: =VLOOKUP(A7,OptionBoard!$A$2:$M$86,10,0) | K7: =VLOOKUP(A7,OptionBoard!$A$2:$M$86,11,FALSE()) | L7: =VLOOKUP(A7,OptionBoard!$A$2:$M$86,12,0) | M7: =VLOOKUP(A7,OptionBoard!$A$2:$M$86,13,0) | N7: =Portfolio!J15 | O7: buy | P7: =Portfolio!I15 | R7: =G7 | S7: =VLOOKUP(A7,OptionBoard!$A$2:$G$93,7,FALSE()) | U7: =R7-S7
A8: =Portfolio!H16 | B8: =VLOOKUP(A8,OptionBoard!$A$2:$M$86,2,FALSE()) | C8: =VLOOKUP(A8,OptionBoard!$A$2:$M$86,3,0) | D8: =VLOOKUP(A8,OptionBoard!$A$2:$M$86,4,0) | E8: =VLOOKUP(A8,OptionBoard!$A$2:$M$86,5,0) | F8: =VLOOKUP(A8,OptionBoard!$A$2:$M$86,6,0) | G8: =N8/P8 | H8: =VLOOKUP(A8,OptionBoard!$A$2:$M$86,8,0) | I8: =VLOOKUP(A8,OptionBoard!$A$2:$M$86,9,0) | J8: =VLOOKUP(A8,OptionBoard!$A$2:$M$86,10,0) | K8: =VLOOKUP(A8,OptionBoard!$A$2:$M$86,11,FALSE()) | L8: =VLOOKUP(A8,OptionBoard!$A$2:$M$86,12,0) | M8: =VLOOKUP(A8,OptionBoard!$A$2:$M$86,13,0) | N8: =Portfolio!J16 | O8: buy | P8: =Portfolio!I16 | R8: =G8 | S8: =VLOOKUP(A8,OptionBoard!$A$2:$G$93,7,FALSE()) | U8: =R8-S8
A9: =Portfolio!H17 | B9: =VLOOKUP(A9,OptionBoard!$A$2:$M$86,2,FALSE()) | C9: =VLOOKUP(A9,OptionBoard!$A$2:$M$86,3,0) | D9: =VLOOKUP(A9,OptionBoard!$A$2:$M$86,4,0) | E9: =VLOOKUP(A9,OptionBoard!$A$2:$M$86,5,0) | F9: =VLOOKUP(A9,OptionBoard!$A$2:$M$86,6,0) | G9: 1.76 | H9: =VLOOKUP(A9,OptionBoard!$A$2:$M$86,8,0) | I9: =VLOOKUP(A9,OptionBoard!$A$2:$M$86,9,0) | J9: =VLOOKUP(A9,OptionBoard!$A$2:$M$86,10,0) | K9: =VLOOKUP(A9,OptionBoard!$A$2:$M$86,11,FALSE()) | L9: =VLOOKUP(A9,OptionBoard!$A$2:$M$86,12,0) | M9: =VLOOKUP(A9,OptionBoard!$A$2:$M$86,13,0) | N9: =G9*P9 | O9: buy | P9: =Portfolio!I17 | R9: =G9 | S9: =VLOOKUP(A9,OptionBoard!$A$2:$G$93,7,FALSE()) | U9: =R9-S9
A10: =Portfolio!H18 | B10: =VLOOKUP(A10,OptionBoard!$A$2:$M$86,2,FALSE()) | C10: =VLOOKUP(A10,OptionBoard!$A$2:$M$86,3,0) | D10: =VLOOKUP(A10,OptionBoard!$A$2:$M$86,4,0) | E10: =VLOOKUP(A10,OptionBoard!$A$2:$M$86,5,0) | F10: =VLOOKUP(A10,OptionBoard!$A$2:$M$86,6,0) | G10: 2.15 | H10: =VLOOKUP(A10,OptionBoard!$A$2:$M$86,8,0) | I10: =VLOOKUP(A10,OptionBoard!$A$2:$M$86,9,0) | J10: =VLOOKUP(A10,OptionBoard!$A$2:$M$86,10,0) | K10: =VLOOKUP(A10,OptionBoard!$A$2:$M$86,11,FALSE()) | L10: =VLOOKUP(A10,OptionBoard!$A$2:$M$86,12,0) | M10: =VLOOKUP(A10,OptionBoard!$A$2:$M$86,13,0) | N10: =G10*P10 | O10: buy | P10: =Portfolio!I18 | R10: =G10 | S10: =VLOOKUP(A10,OptionBoard!$A$2:$G$93,7,FALSE()) | U10: =R10-S10
A11: =Portfolio!H19 | B11: =VLOOKUP(A11,OptionBoard!$A$2:$M$86,2,FALSE()) | C11: =VLOOKUP(A11,OptionBoard!$A$2:$M$86,3,0) | D11: =VLOOKUP(A11,OptionBoard!$A$2:$M$86,4,0) | E11: =VLOOKUP(A11,OptionBoard!$A$2:$M$86,5,0) | F11: =VLOOKUP(A11,OptionBoard!$A$2:$M$86,6,0) | G11: 9.61 | H11: =VLOOKUP(A11,OptionBoard!$A$2:$M$86,8,0) | I11: =VLOOKUP(A11,OptionBoard!$A$2:$M$86,9,0) | J11: =VLOOKUP(A11,OptionBoard!$A$2:$M$86,10,0) | K11: =VLOOKUP(A11,OptionBoard!$A$2:$M$86,11,FALSE()) | L11: =VLOOKUP(A11,OptionBoard!$A$2:$M$86,12,0) | M11: =VLOOKUP(A11,OptionBoard!$A$2:$M$86,13,0) | N11: =G11*P11 | O11: buy | P11: =Portfolio!I19 | R11: =G11 | S11: =VLOOKUP(A11,OptionBoard!$A$2:$G$93,7,FALSE()) | U11: =R11-S11
A12: =Portfolio!H20 | B12: =VLOOKUP(A12,OptionBoard!$A$2:$M$86,2,FALSE()) | C12: =VLOOKUP(A12,OptionBoard!$A$2:$M$86,3,0) | D12: =VLOOKUP(A12,OptionBoard!$A$2:$M$86,4,0) | E12: =VLOOKUP(A12,OptionBoard!$A$2:$M$86,5,0) | F12: =VLOOKUP(A12,OptionBoard!$A$2:$M$86,6,0) | G12: 0.48 | H12: =VLOOKUP(A12,OptionBoard!$A$2:$M$86,8,0) | I12: =VLOOKUP(A12,OptionBoard!$A$2:$M$86,9,0) | J12: =VLOOKUP(A12,OptionBoard!$A$2:$M$86,10,0) | K12: =VLOOKUP(A12,OptionBoard!$A$2:$M$86,11,FALSE()) | L12: =VLOOKUP(A12,OptionBoard!$A$2:$M$86,12,0) | M12: =VLOOKUP(A12,OptionBoard!$A$2:$M$86,13,0) | N12: =G12*P12 | O12: buy | P12: =Portfolio!I20 | R12: =G12 | S12: =VLOOKUP(A12,OptionBoard!$A$2:$G$93,7,FALSE())
A13: =Portfolio!H21 | B13: =VLOOKUP(A13,OptionBoard!$A$2:$M$86,2,FALSE()) | C13: =VLOOKUP(A13,OptionBoard!$A$2:$M$86,3,0) | D13: =VLOOKUP(A13,OptionBoard!$A$2:$M$86,4,0) | E13: =VLOOKUP(A13,OptionBoard!$A$2:$M$86,5,0) | F13: =VLOOKUP(A13,OptionBoard!$A$2:$M$86,6,0) | G13: 1.96 | H13: =VLOOKUP(A13,OptionBoard!$A$2:$M$86,8,0) | I13: =VLOOKUP(A13,OptionBoard!$A$2:$M$86,9,0) | J13: =VLOOKUP(A13,OptionBoard!$A$2:$M$86,10,0) | K13: =VLOOKUP(A13,OptionBoard!$A$2:$M$86,11,FALSE()) | L13: =VLOOKUP(A13,OptionBoard!$A$2:$M$86,12,0) | M13: =VLOOKUP(A13,OptionBoard!$A$2:$M$86,13,0) | N13: =G13*P13 | O13: buy | P13: =Portfolio!I21 | R13: =G13 | S13: =VLOOKUP(A13,OptionBoard!$A$2:$G$93,7,FALSE())
A14: =Portfolio!H22 | B14: =VLOOKUP(A14,OptionBoard!$A$2:$M$86,2,FALSE()) | C14: =VLOOKUP(A14,OptionBoard!$A$2:$M$86,3,0) | D14: =VLOOKUP(A14,OptionBoard!$A$2:$M$86,4,0) | E14: =VLOOKUP(A14,OptionBoard!$A$2:$M$86,5,0) | F14: =VLOOKUP(A14,OptionBoard!$A$2:$M$86,6,0) | G14: 2.3 | H14: =VLOOKUP(A14,OptionBoard!$A$2:$M$86,8,0) | I14: =VLOOKUP(A14,OptionBoard!$A$2:$M$86,9,0) | J14: =VLOOKUP(A14,OptionBoard!$A$2:$M$86,10,0) | K14: =VLOOKUP(A14,OptionBoard!$A$2:$M$86,11,FALSE()) | L14: =VLOOKUP(A14,OptionBoard!$A$2:$M$86,12,0) | M14: =VLOOKUP(A14,OptionBoard!$A$2:$M$86,13,0) | N14: =G14*P14 | O14: buy | P14: =Portfolio!I22 | R14: =G14 | S14: =VLOOKUP(A14,OptionBoard!$A$2:$G$93,7,FALSE())
A15: =Portfolio!H23 | B15: =VLOOKUP(A15,OptionBoard!$A$2:$M$86,2,FALSE()) | C15: =VLOOKUP(A15,OptionBoard!$A$2:$M$86,3,0) | D15: =VLOOKUP(A15,OptionBoard!$A$2:$M$86,4,0) | E15: =VLOOKUP(A15,OptionBoard!$A$2:$M$86,5,0) | F15: =VLOOKUP(A15,OptionBoard!$A$2:$M$86,6,0) | G15: 1.42 | H15: =VLOOKUP(A15,OptionBoard!$A$2:$M$86,8,0) | I15: =VLOOKUP(A15,OptionBoard!$A$2:$M$86,9,0) | J15: =VLOOKUP(A15,OptionBoard!$A$2:$M$86,10,0) | K15: =VLOOKUP(A15,OptionBoard!$A$2:$M$86,11,FALSE()) | L15: =VLOOKUP(A15,OptionBoard!$A$2:$M$86,12,0) | M15: =VLOOKUP(A15,OptionBoard!$A$2:$M$86,13,0) | N15: =G15*P15 | O15: buy | P15: =Portfolio!I23 | R15: =G15 | S15: =VLOOKUP(A15,OptionBoard!$A$2:$G$93,7,FALSE())
A18: Now_Greeks | C18: =(IF($O$2="buy",1,-1) * C2 * P2)+(IF($O$3="buy",1,-1) * C3 * P3)+(IF($O$4="buy",1,-1) * C4 * P4)+(IF($O$5="buy",1,-1) * C5 * P5)+(IF($O$6="buy",1,-1) * C6 * P6)+(IF($O$7="buy",1,-1) * C7 * P7)+(IF($O$8="buy",1,-1) * C8 * P8)+(IF($O$9="buy",1,-1) * C9 * P9)+(IF($O$10="buy",1,-1) * C10 * P10)+(IF($O$11="buy",1,-1) * C11 * P11)+(IF($O$12="buy",1,-1) * C12 * P12)+(IF($O$13="buy",1,-1) * C13 * P13)+(IF($O$14="buy",1,-1) * C14 * P14)+(IF($O$15="buy",1,-1) * C15 * P15) | D18: =(IF($O$2="buy",1,-1) * D2 * P2)+(IF($O$3="buy",1,-1) * D3 * P3)+(IF($O$4="buy",1,-1) * D4 * P4)+(IF($O$5="buy",1,-1) * D5 * P5)+(IF($O$6="buy",1,-1) * D6 * P6)+(IF($O$7="buy",1,-1) * D7 * P7)+(IF($O$8="buy",1,-1) * D8 * P8)+(IF($O$9="buy",1,-1) * D9 * P9)+(IF($O$10="buy",1,-1) * D10 * P10)+(IF($O$11="buy",1,-1) * D11 * P11)+(IF($O$12="buy",1,-1) * D12 * P12)+(IF($O$13="buy",1,-1) * D13 * P13)+(IF($O$14="buy",1,-1) * D14 * P14)+(IF($O$15="buy",1,-1) * D15 * P15) | E18: =(IF($O$2="buy",1,-1) * E2 * P2)+(IF($O$3="buy",1,-1) * E3 * P3)+(IF($O$4="buy",1,-1) * E4 * P4)+(IF($O$5="buy",1,-1) * E5 * P5)+(IF($O$6="buy",1,-1) * E6 * P6)+(IF($O$7="buy",1,-1) * E7 * P7)+(IF($O$8="buy",1,-1) * E8 * P8)+(IF($O$9="buy",1,-1) * E9 * P9)+(IF($O$10="buy",1,-1) * E10 * P10)+(IF($O$11="buy",1,-1) * E11 * P11)+(IF($O$12="buy",1,-1) * E12 * P12)+(IF($O$13="buy",1,-1) * E13 * P13)+(IF($O$14="buy",1,-1) * E14 * P14)+(IF($O$15="buy",1,-1) * E15 * P15) | F18: =(IF($O$2="buy",1,-1) * F2 * P2)+(IF($O$3="buy",1,-1) * F3 * P3)+(IF($O$4="buy",1,-1) * F4 * P4)+(IF($O$5="buy",1,-1) * F5 * P5)+(IF($O$6="buy",1,-1) * F6 * P6)+(IF($O$7="buy",1,-1) * F7 * P7)+(IF($O$8="buy",1,-1) * F8 * P8)+(IF($O$9="buy",1,-1) * F9 * P9)+(IF($O$10="buy",1,-1) * F10 * P10)+(IF($O$11="buy",1,-1) * F11 * P11)+(IF($O$12="buy",1,-1) * F12 * P12)+(IF($O$13="buy",1,-1) * F13 * P13)+(IF($O$14="buy",1,-1) * F14 * P14)+(IF($O$15="buy",1,-1) * F15 * P15) | G18: =(IF($O$2="buy",1,-1) * G2 * P2)+(IF($O$3="buy",1,-1) * G3 * P3)+(IF($O$4="buy",1,-1) * G4 * P4)+(IF($O$5="buy",1,-1) * G5 * P5)+(IF($O$6="buy",1,-1) * G6 * P6)+(IF($O$7="buy",1,-1) * G7 * P7)+(IF($O$8="buy",1,-1) * G8 * P8)+(IF($O$9="buy",1,-1) * G9 * P9)+(IF($O$10="buy",1,-1) * G10 * P10)+(IF($O$11="buy",1,-1) * G11 * P11)+(IF($O$12="buy",1,-1) * G12 * P12)+(IF($O$13="buy",1,-1) * G13 * P13)+(IF($O$14="buy",1,-1) * G14 * P14)+(IF($O$15="buy",1,-1) * G15 * P15) | M18: =M2*P2+M3*P3+M5*P5+M4*P4+M6*P6+M7*P7+M8*P8+M9*P9+M10*P10+M11*P11+M12*P12+M13*P13+M14*P14+M15*P15 | S18: =F18/C18
A20: =A2 | C20: delta | D20: gamma | E20: vega | F20: theta | G20: mark_price | I20: d1 | J20: d2
B21: =Portfolio!B28 | C21: =IF($O$2="sell",-1,1) * IF($K$2="call", NORMDIST(I21,0,1,1), NORMDIST(I21,0,1,1)-1 ) * $P$2 | D21: =IF($O$2="sell",-1,1) * NORMDIST(I21,0,1,0)/(B21*$H$2*SQRT($J$2)) * $P$2 | E21: =IF($O$2="sell",-1,1) * (B21*NORMDIST(I21,0,1,0)*SQRT($J$2)/365) * $P$2 | F21: =IF($O$2="sell",-1,1) * (-(B21*NORMDIST(I21,0,1,0)*$H$2)/(2*SQRT($J$2))/365) *$P$2 | G21: =IF($O$2="buy",1,-1)*( IF($K$2="call",B21*NORMDIST(I21,0,1,1) - $B$2*NORMDIST(J21,0,1,1),$B$2*NORMDIST(-J21,0,1,1) - B21*NORMDIST(-I21,0,1,1) ) - $G$2) * $P$2 | I21: =(LN(B21/$B$2)+($H$2^2/2)*($J$2))/($H$2*SQRT($J$2)) | J21: =I21 - $H$2*SQRT($J$2)
B22: =Portfolio!B29 | C22: =IF($O$2="sell",-1,1) * IF($K$2="call", NORMDIST(I22,0,1,1), NORMDIST(I22,0,1,1)-1 ) * $P$2 | D22: =IF($O$2="sell",-1,1) * NORMDIST(I22,0,1,0)/(B22*$H$2*SQRT($J$2)) * $P$2 | E22: =IF($O$2="sell",-1,1) * (B22*NORMDIST(I22,0,1,0)*SQRT($J$2)/365) * $P$2 | F22: =IF($O$2="sell",-1,1) * (-(B22*NORMDIST(I22,0,1,0)*$H$2)/(2*SQRT($J$2))/365) *$P$2 | G22: =IF($O$2="buy",1,-1)*( IF($K$2="call",B22*NORMDIST(I22,0,1,1) - $B$2*NORMDIST(J22,0,1,1),$B$2*NORMDIST(-J22,0,1,1) - B22*NORMDIST(-I22,0,1,1) ) - $G$2) * $P$2 | I22: =(LN(B22/$B$2)+($H$2^2/2)*($J$2))/($H$2*SQRT($J$2)) | J22: =I22 - $H$2*SQRT($J$2)
B23: =Portfolio!B30 | C23: =IF($O$2="sell",-1,1) * IF($K$2="call", NORMDIST(I23,0,1,1), NORMDIST(I23,0,1,1)-1 ) * $P$2 | D23: =IF($O$2="sell",-1,1) * NORMDIST(I23,0,1,0)/(B23*$H$2*SQRT($J$2)) * $P$2 | E23: =IF($O$2="sell",-1,1) * (B23*NORMDIST(I23,0,1,0)*SQRT($J$2)/365) * $P$2 | F23: =IF($O$2="sell",-1,1) * (-(B23*NORMDIST(I23,0,1,0)*$H$2)/(2*SQRT($J$2))/365) *$P$2 | G23: =IF($O$2="buy",1,-1)*( IF($K$2="call",B23*NORMDIST(I23,0,1,1) - $B$2*NORMDIST(J23,0,1,1),$B$2*NORMDIST(-J23,0,1,1) - B23*NORMDIST(-I23,0,1,1) ) - $G$2) * $P$2 | I23: =(LN(B23/$B$2)+($H$2^2/2)*($J$2))/($H$2*SQRT($J$2)) | J23: =I23 - $H$2*SQRT($J$2)
B24: =Portfolio!B31 | C24: =IF($O$2="sell",-1,1) * IF($K$2="call", NORMDIST(I24,0,1,1), NORMDIST(I24,0,1,1)-1 ) * $P$2 | D24: =IF($O$2="sell",-1,1) * NORMDIST(I24,0,1,0)/(B24*$H$2*SQRT($J$2)) * $P$2 | E24: =IF($O$2="sell",-1,1) * (B24*NORMDIST(I24,0,1,0)*SQRT($J$2)/365) * $P$2 | F24: =IF($O$2="sell",-1,1) * (-(B24*NORMDIST(I24,0,1,0)*$H$2)/(2*SQRT($J$2))/365) *$P$2 | G24: =IF($O$2="buy",1,-1)*( IF($K$2="call",B24*NORMDIST(I24,0,1,1) - $B$2*NORMDIST(J24,0,1,1),$B$2*NORMDIST(-J24,0,1,1) - B24*NORMDIST(-I24,0,1,1) ) - $G$2) * $P$2 | I24: =(LN(B24/$B$2)+($H$2^2/2)*($J$2))/($H$2*SQRT($J$2)) | J24: =I24 - $H$2*SQRT($J$2)
B25: =Portfolio!B32 | C25: =IF($O$2="sell",-1,1) * IF($K$2="call", NORMDIST(I25,0,1,1), NORMDIST(I25,0,1,1)-1 ) * $P$2 | D25: =IF($O$2="sell",-1,1) * NORMDIST(I25,0,1,0)/(B25*$H$2*SQRT($J$2)) * $P$2 | E25: =IF($O$2="sell",-1,1) * (B25*NORMDIST(I25,0,1,0)*SQRT($J$2)/365) * $P$2 | F25: =IF($O$2="sell",-1,1) * (-(B25*NORMDIST(I25,0,1,0)*$H$2)/(2*SQRT($J$2))/365) *$P$2 | G25: =IF($O$2="buy",1,-1)*( IF($K$2="call",B25*NORMDIST(I25,0,1,1) - $B$2*NORMDIST(J25,0,1,1),$B$2*NORMDIST(-J25,0,1,1) - B25*NORMDIST(-I25,0,1,1) ) - $G$2) * $P$2 | I25: =(LN(B25/$B$2)+($H$2^2/2)*($J$2))/($H$2*SQRT($J$2)) | J25: =I25 - $H$2*SQRT($J$2)
B26: =Portfolio!B33 | C26: =IF($O$2="sell",-1,1) * IF($K$2="call", NORMDIST(I26,0,1,1), NORMDIST(I26,0,1,1)-1 ) * $P$2 | D26: =IF($O$2="sell",-1,1) * NORMDIST(I26,0,1,0)/(B26*$H$2*SQRT($J$2)) * $P$2 | E26: =IF($O$2="sell",-1,1) * (B26*NORMDIST(I26,0,1,0)*SQRT($J$2)/365) * $P$2 | F26: =IF($O$2="sell",-1,1) * (-(B26*NORMDIST(I26,0,1,0)*$H$2)/(2*SQRT($J$2))/365) *$P$2 | G26: =IF($O$2="buy",1,-1)*( IF($K$2="call",B26*NORMDIST(I26,0,1,1) - $B$2*NORMDIST(J26,0,1,1),$B$2*NORMDIST(-J26,0,1,1) - B26*NORMDIST(-I26,0,1,1) ) - $G$2) * $P$2 | I26: =(LN(B26/$B$2)+($H$2^2/2)*($J$2))/($H$2*SQRT($J$2)) | J26: =I26 - $H$2*SQRT($J$2)
B27: =Portfolio!B34 | C27: =IF($O$2="sell",-1,1) * IF($K$2="call", NORMDIST(I27,0,1,1), NORMDIST(I27,0,1,1)-1 ) * $P$2 | D27: =IF($O$2="sell",-1,1) * NORMDIST(I27,0,1,0)/(B27*$H$2*SQRT($J$2)) * $P$2 | E27: =IF($O$2="sell",-1,1) * (B27*NORMDIST(I27,0,1,0)*SQRT($J$2)/365) * $P$2 | F27: =IF($O$2="sell",-1,1) * (-(B27*NORMDIST(I27,0,1,0)*$H$2)/(2*SQRT($J$2))/365) *$P$2 | G27: =IF($O$2="buy",1,-1)*( IF($K$2="call",B27*NORMDIST(I27,0,1,1) - $B$2*NORMDIST(J27,0,1,1),$B$2*NORMDIST(-J27,0,1,1) - B27*NORMDIST(-I27,0,1,1) ) - $G$2) * $P$2 | I27: =(LN(B27/$B$2)+($H$2^2/2)*($J$2))/($H$2*SQRT($J$2)) | J27: =I27 - $H$2*SQRT($J$2)
B28: =Portfolio!B35 | C28: =IF($O$2="sell",-1,1) * IF($K$2="call", NORMDIST(I28,0,1,1), NORMDIST(I28,0,1,1)-1 ) * $P$2 | D28: =IF($O$2="sell",-1,1) * NORMDIST(I28,0,1,0)/(B28*$H$2*SQRT($J$2)) * $P$2 | E28: =IF($O$2="sell",-1,1) * (B28*NORMDIST(I28,0,1,0)*SQRT($J$2)/365) * $P$2 | F28: =IF($O$2="sell",-1,1) * (-(B28*NORMDIST(I28,0,1,0)*$H$2)/(2*SQRT($J$2))/365) *$P$2 | G28: =IF($O$2="buy",1,-1)*( IF($K$2="call",B28*NORMDIST(I28,0,1,1) - $B$2*NORMDIST(J28,0,1,1),$B$2*NORMDIST(-J28,0,1,1) - B28*NORMDIST(-I28,0,1,1) ) - $G$2) * $P$2 | I28: =(LN(B28/$B$2)+($H$2^2/2)*($J$2))/($H$2*SQRT($J$2)) | J28: =I28 - $H$2*SQRT($J$2)
B29: =Portfolio!B36 | C29: =IF($O$2="sell",-1,1) * IF($K$2="call", NORMDIST(I29,0,1,1), NORMDIST(I29,0,1,1)-1 ) * $P$2 | D29: =IF($O$2="sell",-1,1) * NORMDIST(I29,0,1,0)/(B29*$H$2*SQRT($J$2)) * $P$2 | E29: =IF($O$2="sell",-1,1) * (B29*NORMDIST(I29,0,1,0)*SQRT($J$2)/365) * $P$2 | F29: =IF($O$2="sell",-1,1) * (-(B29*NORMDIST(I29,0,1,0)*$H$2)/(2*SQRT($J$2))/365) *$P$2 | G29: =IF($O$2="buy",1,-1)*( IF($K$2="call",B29*NORMDIST(I29,0,1,1) - $B$2*NORMDIST(J29,0,1,1),$B$2*NORMDIST(-J29,0,1,1) - B29*NORMDIST(-I29,0,1,1) ) - $G$2) * $P$2 | I29: =(LN(B29/$B$2)+($H$2^2/2)*($J$2))/($H$2*SQRT($J$2)) | J29: =I29 - $H$2*SQRT($J$2)
B30: =Portfolio!B37 | C30: =IF($O$2="sell",-1,1) * IF($K$2="call", NORMDIST(I30,0,1,1), NORMDIST(I30,0,1,1)-1 ) * $P$2 | D30: =IF($O$2="sell",-1,1) * NORMDIST(I30,0,1,0)/(B30*$H$2*SQRT($J$2)) * $P$2 | E30: =IF($O$2="sell",-1,1) * (B30*NORMDIST(I30,0,1,0)*SQRT($J$2)/365) * $P$2 | F30: =IF($O$2="sell",-1,1) * (-(B30*NORMDIST(I30,0,1,0)*$H$2)/(2*SQRT($J$2))/365) *$P$2 | G30: =IF($O$2="buy",1,-1)*( IF($K$2="call",B30*NORMDIST(I30,0,1,1) - $B$2*NORMDIST(J30,0,1,1),$B$2*NORMDIST(-J30,0,1,1) - B30*NORMDIST(-I30,0,1,1) ) - $G$2) * $P$2 | I30: =(LN(B30/$B$2)+($H$2^2/2)*($J$2))/($H$2*SQRT($J$2)) | J30: =I30 - $H$2*SQRT($J$2)
B31: =Portfolio!B38 | C31: =IF($O$2="sell",-1,1) * IF($K$2="call", NORMDIST(I31,0,1,1), NORMDIST(I31,0,1,1)-1 ) * $P$2 | D31: =IF($O$2="sell",-1,1) * NORMDIST(I31,0,1,0)/(B31*$H$2*SQRT($J$2)) * $P$2 | E31: =IF($O$2="sell",-1,1) * (B31*NORMDIST(I31,0,1,0)*SQRT($J$2)/365) * $P$2 | F31: =IF($O$2="sell",-1,1) * (-(B31*NORMDIST(I31,0,1,0)*$H$2)/(2*SQRT($J$2))/365) *$P$2 | G31: =IF($O$2="buy",1,-1)*( IF($K$2="call",B31*NORMDIST(I31,0,1,1) - $B$2*NORMDIST(J31,0,1,1),$B$2*NORMDIST(-J31,0,1,1) - B31*NORMDIST(-I31,0,1,1) ) - $G$2) * $P$2 | I31: =(LN(B31/$B$2)+($H$2^2/2)*($J$2))/($H$2*SQRT($J$2)) | J31: =I31 - $H$2*SQRT($J$2)
B32: =Portfolio!B39 | C32: =IF($O$2="sell",-1,1) * IF($K$2="call", NORMDIST(I32,0,1,1), NORMDIST(I32,0,1,1)-1 ) * $P$2 | D32: =IF($O$2="sell",-1,1) * NORMDIST(I32,0,1,0)/(B32*$H$2*SQRT($J$2)) * $P$2 | E32: =IF($O$2="sell",-1,1) * (B32*NORMDIST(I32,0,1,0)*SQRT($J$2)/365) * $P$2 | F32: =IF($O$2="sell",-1,1) * (-(B32*NORMDIST(I32,0,1,0)*$H$2)/(2*SQRT($J$2))/365) *$P$2 | G32: =IF($O$2="buy",1,-1)*( IF($K$2="call",B32*NORMDIST(I32,0,1,1) - $B$2*NORMDIST(J32,0,1,1),$B$2*NORMDIST(-J32,0,1,1) - B32*NORMDIST(-I32,0,1,1) ) - $G$2) * $P$2 | I32: =(LN(B32/$B$2)+($H$2^2/2)*($J$2))/($H$2*SQRT($J$2)) | J32: =I32 - $H$2*SQRT($J$2)
... B47: =Portfolio!B54 | C47: =IF($O$2="sell",-1,1) * IF($K$2="call", NORMDIST(I47,0,1,1), NORMDIST(I47,0,1,1)-1 ) * $P$2 | D47: =IF($O$2="sell",-1,1) * NORMDIST(I47,0,1,0)/(B47*$H$2*SQRT($J$2)) * $P$2 | E47: =IF($O$2="sell",-1,1) * (B47*NORMDIST(I47,0,1,0)*SQRT($J$2)/365) * $P$2 | F47: =IF($O$2="sell",-1,1) * (-(B47*NORMDIST(I47,0,1,0)*$H$2)/(2*SQRT($J$2))/365) *$P$2 | G47: =IF($O$2="buy",1,-1)*( IF($K$2="call",B47*NORMDIST(I47,0,1,1) - $B$2*NORMDIST(J47,0,1,1),$B$2*NORMDIST(-J47,0,1,1) - B47*NORMDIST(-I47,0,1,1) ) - $G$2) * $P$2 | I47: =(LN(B47/$B$2)+($H$2^2/2)*($J$2))/($H$2*SQRT($J$2)) | J47: =I47 - $H$2*SQRT($J$2)
A49: =A3 | C49: delta | D49: gamma | E49: vega | F49: theta | G49: mark_price | I49: d1 | J49: d2
B50: =B21 | C50: =IF($O$3="sell",-1,1) * IF($K$3="call", NORMDIST(I50,0,1,1), NORMDIST(I50,0,1,1)-1 ) * $P$3 | D50: =IF($O$3="sell",-1,1) * NORMDIST(I50,0,1,0)/(B50*$H$3*SQRT($J$3)) * $P$3 | E50: =IF($O$3="sell",-1,1) * (B50*NORMDIST(I50,0,1,0)*SQRT($J$3)/365) * $P$3 | F50: =IF($O$3="sell",-1,1) * (-(B50*NORMDIST(I50,0,1,0)*$H$3)/(2*SQRT($J$3))/365) *$P$3 | G50: =IF($O$3="buy",1,-1)*( IF($K$3="call",B50*NORMDIST(I50,0,1,1) - $B$3*NORMDIST(J50,0,1,1),$B$3*NORMDIST(-J50,0,1,1) - B50*NORMDIST(-I50,0,1,1) ) - $G$3) * $P$3 | I50: =(LN(B50/$B$3)+($H$3^2/2)*($J$3))/($H$3*SQRT($J$3)) | J50: =I50 - $H$3*SQRT($J$3)
B51: =B22 | C51: =IF($O$3="sell",-1,1) * IF($K$3="call", NORMDIST(I51,0,1,1), NORMDIST(I51,0,1,1)-1 ) * $P$3 | D51: =IF($O$3="sell",-1,1) * NORMDIST(I51,0,1,0)/(B51*$H$3*SQRT($J$3)) * $P$3 | E51: =IF($O$3="sell",-1,1) * (B51*NORMDIST(I51,0,1,0)*SQRT($J$3)/365) * $P$3 | F51: =IF($O$3="sell",-1,1) * (-(B51*NORMDIST(I51,0,1,0)*$H$3)/(2*SQRT($J$3))/365) *$P$3 | G51: =IF($O$3="buy",1,-1)*( IF($K$3="call",B51*NORMDIST(I51,0,1,1) - $B$3*NORMDIST(J51,0,1,1),$B$3*NORMDIST(-J51,0,1,1) - B51*NORMDIST(-I51,0,1,1) ) - $G$3) * $P$3 | I51: =(LN(B51/$B$3)+($H$3^2/2)*($J$3))/($H$3*SQRT($J$3)) | J51: =I51 - $H$3*SQRT($J$3)
B52: =B23 | C52: =IF($O$3="sell",-1,1) * IF($K$3="call", NORMDIST(I52,0,1,1), NORMDIST(I52,0,1,1)-1 ) * $P$3 | D52: =IF($O$3="sell",-1,1) * NORMDIST(I52,0,1,0)/(B52*$H$3*SQRT($J$3)) * $P$3 | E52: =IF($O$3="sell",-1,1) * (B52*NORMDIST(I52,0,1,0)*SQRT($J$3)/365) * $P$3 | F52: =IF($O$3="sell",-1,1) * (-(B52*NORMDIST(I52,0,1,0)*$H$3)/(2*SQRT($J$3))/365) *$P$3 | G52: =IF($O$3="buy",1,-1)*( IF($K$3="call",B52*NORMDIST(I52,0,1,1) - $B$3*NORMDIST(J52,0,1,1),$B$3*NORMDIST(-J52,0,1,1) - B52*NORMDIST(-I52,0,1,1) ) - $G$3) * $P$3 | I52: =(LN(B52/$B$3)+($H$3^2/2)*($J$3))/($H$3*SQRT($J$3)) | J52: =I52 - $H$3*SQRT($J$3)
B53: =B24 | C53: =IF($O$3="sell",-1,1) * IF($K$3="call", NORMDIST(I53,0,1,1), NORMDIST(I53,0,1,1)-1 ) * $P$3 | D53: =IF($O$3="sell",-1,1) * NORMDIST(I53,0,1,0)/(B53*$H$3*SQRT($J$3)) * $P$3 | E53: =IF($O$3="sell",-1,1) * (B53*NORMDIST(I53,0,1,0)*SQRT($J$3)/365) * $P$3 | F53: =IF($O$3="sell",-1,1) * (-(B53*NORMDIST(I53,0,1,0)*$H$3)/(2*SQRT($J$3))/365) *$P$3 | G53: =IF($O$3="buy",1,-1)*( IF($K$3="call",B53*NORMDIST(I53,0,1,1) - $B$3*NORMDIST(J53,0,1,1),$B$3*NORMDIST(-J53,0,1,1) - B53*NORMDIST(-I53,0,1,1) ) - $G$3) * $P$3 | I53: =(LN(B53/$B$3)+($H$3^2/2)*($J$3))/($H$3*SQRT($J$3)) | J53: =I53 - $H$3*SQRT($J$3)
B54: =B25 | C54: =IF($O$3="sell",-1,1) * IF($K$3="call", NORMDIST(I54,0,1,1), NORMDIST(I54,0,1,1)-1 ) * $P$3 | D54: =IF($O$3="sell",-1,1) * NORMDIST(I54,0,1,0)/(B54*$H$3*SQRT($J$3)) * $P$3 | E54: =IF($O$3="sell",-1,1) * (B54*NORMDIST(I54,0,1,0)*SQRT($J$3)/365) * $P$3 | F54: =IF($O$3="sell",-1,1) * (-(B54*NORMDIST(I54,0,1,0)*$H$3)/(2*SQRT($J$3))/365) *$P$3 | G54: =IF($O$3="buy",1,-1)*( IF($K$3="call",B54*NORMDIST(I54,0,1,1) - $B$3*NORMDIST(J54,0,1,1),$B$3*NORMDIST(-J54,0,1,1) - B54*NORMDIST(-I54,0,1,1) ) - $G$3) * $P$3 | I54: =(LN(B54/$B$3)+($H$3^2/2)*($J$3))/($H$3*SQRT($J$3)) | J54: =I54 - $H$3*SQRT($J$3)
B55: =B26 | C55: =IF($O$3="sell",-1,1) * IF($K$3="call", NORMDIST(I55,0,1,1), NORMDIST(I55,0,1,1)-1 ) * $P$3 | D55: =IF($O$3="sell",-1,1) * NORMDIST(I55,0,1,0)/(B55*$H$3*SQRT($J$3)) * $P$3 | E55: =IF($O$3="sell",-1,1) * (B55*NORMDIST(I55,0,1,0)*SQRT($J$3)/365) * $P$3 | F55: =IF($O$3="sell",-1,1) * (-(B55*NORMDIST(I55,0,1,0)*$H$3)/(2*SQRT($J$3))/365) *$P$3 | G55: =IF($O$3="buy",1,-1)*( IF($K$3="call",B55*NORMDIST(I55,0,1,1) - $B$3*NORMDIST(J55,0,1,1),$B$3*NORMDIST(-J55,0,1,1) - B55*NORMDIST(-I55,0,1,1) ) - $G$3) * $P$3 | I55: =(LN(B55/$B$3)+($H$3^2/2)*($J$3))/($H$3*SQRT($J$3)) | J55: =I55 - $H$3*SQRT($J$3)
B56: =B27 | C56: =IF($O$3="sell",-1,1) * IF($K$3="call", NORMDIST(I56,0,1,1), NORMDIST(I56,0,1,1)-1 ) * $P$3 | D56: =IF($O$3="sell",-1,1) * NORMDIST(I56,0,1,0)/(B56*$H$3*SQRT($J$3)) * $P$3 | E56: =IF($O$3="sell",-1,1) * (B56*NORMDIST(I56,0,1,0)*SQRT($J$3)/365) * $P$3 | F56: =IF($O$3="sell",-1,1) * (-(B56*NORMDIST(I56,0,1,0)*$H$3)/(2*SQRT($J$3))/365) *$P$3 | G56: =IF($O$3="buy",1,-1)*( IF($K$3="call",B56*NORMDIST(I56,0,1,1) - $B$3*NORMDIST(J56,0,1,1),$B$3*NORMDIST(-J56,0,1,1) - B56*NORMDIST(-I56,0,1,1) ) - $G$3) * $P$3 | I56: =(LN(B56/$B$3)+($H$3^2/2)*($J$3))/($H$3*SQRT($J$3)) | J56: =I56 - $H$3*SQRT($J$3)
B57: =B28 | C57: =IF($O$3="sell",-1,1) * IF($K$3="call", NORMDIST(I57,0,1,1), NORMDIST(I57,0,1,1)-1 ) * $P$3 | D57: =IF($O$3="sell",-1,1) * NORMDIST(I57,0,1,0)/(B57*$H$3*SQRT($J$3)) * $P$3 | E57: =IF($O$3="sell",-1,1) * (B57*NORMDIST(I57,0,1,0)*SQRT($J$3)/365) * $P$3 | F57: =IF($O$3="sell",-1,1) * (-(B57*NORMDIST(I57,0,1,0)*$H$3)/(2*SQRT($J$3))/365) *$P$3 | G57: =IF($O$3="buy",1,-1)*( IF($K$3="call",B57*NORMDIST(I57,0,1,1) - $B$3*NORMDIST(J57,0,1,1),$B$3*NORMDIST(-J57,0,1,1) - B57*NORMDIST(-I57,0,1,1) ) - $G$3) * $P$3 | I57: =(LN(B57/$B$3)+($H$3^2/2)*($J$3))/($H$3*SQRT($J$3)) | J57: =I57 - $H$3*SQRT($J$3)
B58: =B29 | C58: =IF($O$3="sell",-1,1) * IF($K$3="call", NORMDIST(I58,0,1,1), NORMDIST(I58,0,1,1)-1 ) * $P$3 | D58: =IF($O$3="sell",-1,1) * NORMDIST(I58,0,1,0)/(B58*$H$3*SQRT($J$3)) * $P$3 | E58: =IF($O$3="sell",-1,1) * (B58*NORMDIST(I58,0,1,0)*SQRT($J$3)/365) * $P$3 | F58: =IF($O$3="sell",-1,1) * (-(B58*NORMDIST(I58,0,1,0)*$H$3)/(2*SQRT($J$3))/365) *$P$3 | G58: =IF($O$3="buy",1,-1)*( IF($K$3="call",B58*NORMDIST(I58,0,1,1) - $B$3*NORMDIST(J58,0,1,1),$B$3*NORMDIST(-J58,0,1,1) - B58*NORMDIST(-I58,0,1,1) ) - $G$3) * $P$3 | I58: =(LN(B58/$B$3)+($H$3^2/2)*($J$3))/($H$3*SQRT($J$3)) | J58: =I58 - $H$3*SQRT($J$3)
...

Sheet Portfolio
J2: DTE | K2: % просадки
B3: Текущая дата | C3: Текущая цена | H3: Ближний слой | J3: 5-10 | K3: 0 | L3: 0.05
B4: =TODAY() | C4: =OptionBoard!L2 | H4: Средний слой | J4: 10-20 | K4: 0.05 | L4: 0.15
H5: Дальный слой | J5: 20-40 | K5: 0.16 | L5: выше
A7: Информация по портфелю
A9: № | B9: Актив | C9: Количество | D9: Ср.Цена | E9: Pnl | F9: Нач. Стои | H9: symbol | I9: кол | J9: cost | K9: strike | L9: DTE | M9: layer
A10: 1 | B10: SOL | C10: =Actives!D13 | D10: =Actives!E13 | E10: =Actives!H13 | F10: =Actives!F13 | H10: =Far_laeyr!B59 | I10: =Far_laeyr!G59 | J10: =Far_laeyr!H59 | K10: =VLOOKUP(H10,OptionBoard!$A$2:$B$73,2,0) | L10: =VLOOKUP(H10,OptionBoard!$A$2:$I$72,9,0) | M10: 3
H11: =Far_laeyr!B60 | I11: =Far_laeyr!G60 | J11: =Far_laeyr!H60 | K11: =VLOOKUP(H11,OptionBoard!$A$2:$B$73,2,0) | L11: =VLOOKUP(H11,OptionBoard!$A$2:$I$72,9,0) | M11: 3
B12: Лимит | C12: =F10*0.05 | H12: =Far_laeyr!B61 | I12: =Far_laeyr!G61 | J12: =Far_laeyr!H61 | K12: =VLOOKUP(H12,OptionBoard!$A$2:$B$73,2,0) | L12: =VLOOKUP(H12,OptionBoard!$A$2:$I$72,9,0) | M12: 3
B13: Ближний слой | C13: =SUMIF(M$10:M$23,"=1",J$10:J$23) | D13: =0.1*$C$12 | E13: =0.2*$C$12 | H13: =Far_laeyr!B62 | I13: =Far_laeyr!G62 | J13: =Far_laeyr!H62 | K13: =VLOOKUP(H13,OptionBoard!$A$2:$B$73,2,0) | L13: =VLOOKUP(H13,OptionBoard!$A$2:$I$72,9,0) | M13: 3
B14: Средний слой | C14: =SUMIF(M$10:M$23,"=2",J$10:J$23) | D14: =0.3*$C$12 | E14: =0.4*$C$12 | H14: =Far_laeyr!B63 | I14: =Far_laeyr!G63 | J14: =Far_laeyr!H63 | K14: =VLOOKUP(H14,OptionBoard!$A$2:$B$73,2,0) | L14: =VLOOKUP(H14,OptionBoard!$A$2:$I$72,9,0) | M14: 3
B15: Дальный слой | C15: =SUMIF(M$10:M$23,"=3",J$10:J$23) | D15: =0.4*$C$12 | E15: =0.5*$C$12 | H15: =Far_laeyr!B64 | I15: =Far_laeyr!G64 | J15: =Far_laeyr!H64 | K15: =VLOOKUP(H15,OptionBoard!$A$2:$B$73,2,0) | L15: =VLOOKUP(H15,OptionBoard!$A$2:$I$72,9,0) | M15: 3
B16: Стоимость хэджа | C16: =SUM(C13:C15) | H16: =Far_laeyr!B65 | I16: =Far_laeyr!G65 | J16: =Far_laeyr!H65 | K16: =VLOOKUP(H16,OptionBoard!$A$2:$B$73,2,0) | L16: =VLOOKUP(H16,OptionBoard!$A$2:$I$72,9,0) | M16: 3
B17: Запас | C17: =C12-C16 | H17: =MID_laeyr!B62 | I17: =MID_laeyr!G62 | J17: =MID_laeyr!H62 | K17: =VLOOKUP(H17,OptionBoard!$A$2:$B$73,2,0) | L17: =VLOOKUP(H17,OptionBoard!$A$2:$I$72,9,0) | M17: 2
H18: =MID_laeyr!B63 | I18: =MID_laeyr!G63 | J18: =MID_laeyr!H63 | K18: =VLOOKUP(H18,OptionBoard!$A$2:$B$73,2,0) | L18: =VLOOKUP(H18,OptionBoard!$A$2:$I$72,9,0) | M18: 2
B19: Доходный Pnl | C19: =Actives!D36 | H19: =MID_laeyr!B64 | I19: =MID_laeyr!G64 | J19: =MID_laeyr!H64 | K19: =VLOOKUP(H19,OptionBoard!$A$2:$B$73,2,0) | L19: =VLOOKUP(H19,OptionBoard!$A$2:$I$72,9,0) | M19: 2
H20: SOL-17APR26-72-P-USDT | I20: 3 | J20: =Hedge_Total!N12 | K20: =VLOOKUP(H20,OptionBoard!$A$2:$B$73,2,0) | L20: =VLOOKUP(H20,OptionBoard!$A$2:$I$72,9,0) | M20: 1
H21: SOL-17APR26-75-P-USDT | I21: 4 | J21: =Hedge_Total!N13 | K21: =VLOOKUP(H21,OptionBoard!$A$2:$B$73,2,0) | L21: =VLOOKUP(H21,OptionBoard!$A$2:$I$72,9,0) | M21: 1
H22: SOL-17APR26-78-P-USDT | I22: 4 | J22: =Hedge_Total!N14 | K22: =VLOOKUP(H22,OptionBoard!$A$2:$B$73,2,0) | L22: =VLOOKUP(H22,OptionBoard!$A$2:$I$72,9,0) | M22: 1
H23: SOL-17APR26-80-P-USDT | I23: 2 | J23: =Hedge_Total!N15 | K23: =VLOOKUP(H23,OptionBoard!$A$2:$B$73,2,0) | L23: =VLOOKUP(H23,OptionBoard!$A$2:$I$72,9,0) | M23: 1
J24: =SUM(J10:J23)
B26: Activ | H26: Total Options | S26: =H10 | U26: =H11 | W26: =H12 | Y26: =H13 | AA26: =H14 | AC26: =H15 | AE26: =H16 | AG26: =H17 | AI26: =H18 | AK26: =H19 | AM26: =H20 | AO26: =H21 | AQ26: =H22 | AS26: =H23
B27: Price | C27: Efficien Pnl | D27: Efficien Intr | E27: Pnl | F27: %loss | H27: Price | I27: Delta | J27: Pnl | K27: Intrin | L27: Pnl %loss | M27: Int %loss | N27: Pnl_loss | O27: Intrin_Loss | R27: Price | S27: Pnl | T27: Intrin | U27: Pnl | V27: Intrin | W27: Pnl | X27: Intrin | Y27: Pnl | Z27: Intrin | AA27: Pnl | AB27: Intrin | AC27: Pnl | AD27: Intrin | AE27: Pnl | AF27: Intrin | AG27: Pnl | AH27: Intrin | AI27: Pnl | AJ27: Intrin | AK27: Pnl | AL27: Intrin | AM27: Pnl | AN27: Intrin | AO27: Pnl | AP27: Intrin | AQ27: Pnl | AR27: Intrin | AS27: Pnl | AT27: Intrin
B28: =ROUND(D10,0) | C28: =J28/$C$16 | D28: =K28/$C$16 | E28: =($C$10*B28)-$F$10 | F28: =(E28/$F$10) | H28: =B28 | I28: =Hedge_Total!C438 | J28: =Hedge_Total!G438 | K28: =T28+V28+X28+Z28+AB28+AD28+AF28+AH28+AJ28+AL28+AN28+AP28+AR28+AT28 | L28: =N28/$F$10 | M28: =O28/$F$10 | N28: =E28+J28 | O28: =E28+K28 | R28: =B28 | S28: =Hedge_Total!G21 | T28: =IF(B28>$K$10,-1*$J$10,(($K$10-B28)*$I$10)-$J$10) | U28: =Hedge_Total!G50 | V28: =IF(B28>$K$11,-1*$J$11,(($K$11-B28)*$I$11)-$J$11) | W28: =Hedge_Total!G79 | X28: =IF(B28>$K$12,-1*$J$12,(($K$12-B28)*$I$12)-$J$12) | Y28: =Hedge_Total!G108 | Z28: =IF(B28>$K$13,-1*$J$13,(($K$13-B28)*$I$13)-$J$13) | AA28: =Hedge_Total!G138 | AB28: =IF(B28>$K$14,-1*$J$14,(($K$14-B28)*$I$14)-$J$14) | AC28: =Hedge_Total!G168 | AD28: =IF(B28>$K$15,-1*$J$15,(($K$15-B28)*$I$15)-$J$15) | AE28: =Hedge_Total!G198 | AF28: =IF(B28>$K$16,-1*$J$16,(($K$16-B28)*$I$16)-$J$16) | AG28: =Hedge_Total!G228 | AH28: =IF(B28>$K$17,-1*$J$17,(($K$17-B28)*$I$17)-$J$17) | AI28: =Hedge_Total!G258 | AJ28: =IF(B28>$K$18,-1*$J$18,(($K$18-B28)*$I$18)-$J$18) | AK28: =Hedge_Total!G288 | AL28: =IF(B28>$K$19,-1*$J$19,(($K$19-B28)*$I$19)-$J$19) | AM28: =Hedge_Total!G318 | AN28: =IF(B28>$K$20,-1*$J$20,(($K$20-B28)*$I$20)-$J$20) | AO28: =Hedge_Total!G348 | AP28: =IF(B28>$K$21,-1*$J$21,(($K$21-B28)*$I$21)-$J$21) | AQ28: =Hedge_Total!G378 | AR28: =IF(B28>$K$22,-1*$J$22,(($K$22-B28)*$I$22)-$J$22) | AS28: =Hedge_Total!G408 | AT28: =IF(B28>$K$23,-1*$J$23,(($K$23-B28)*$I$23)-$J$23)
B29: =B28-1 | C29: =J29/$C$16 | D29: =K29/$C$16 | E29: =($C$10*B29)-$F$10 | F29: =(E29/$F$10) | H29: =H28-1 | I29: =Hedge_Total!C439 | J29: =Hedge_Total!G439 | K29: =T29+V29+X29+Z29+AB29+AD29+AF29+AH29+AJ29+AL29+AN29+AP29+AR29+AT29 | L29: =N29/$F$10 | M29: =O29/$F$10 | N29: =E29+J29 | O29: =E29+K29 | P29: =J30-2*J29+J28 | R29: =R28-1 | S29: =Hedge_Total!G22 | T29: =IF(B29>$K$10,-1*$J$10,(($K$10-B29)*$I$10)-$J$10) | U29: =Hedge_Total!G51 | V29: =IF(B29>$K$11,-1*$J$11,(($K$11-B29)*$I$11)-$J$11) | W29: =Hedge_Total!G80 | X29: =IF(B29>$K$12,-1*$J$12,(($K$12-B29)*$I$12)-$J$12) | Y29: =Hedge_Total!G109 | Z29: =IF(B29>$K$13,-1*$J$13,(($K$13-B29)*$I$13)-$J$13) | AA29: =Hedge_Total!G139 | AB29: =IF(B29>$K$14,-1*$J$14,(($K$14-B29)*$I$14)-$J$14) | AC29: =Hedge_Total!G169 | AD29: =IF(B29>$K$15,-1*$J$15,(($K$15-B29)*$I$15)-$J$15) | AE29: =Hedge_Total!G199 | AF29: =IF(B29>$K$16,-1*$J$16,(($K$16-B29)*$I$16)-$J$16) | AG29: =Hedge_Total!G229 | AH29: =IF(B29>$K$17,-1*$J$17,(($K$17-B29)*$I$17)-$J$17) | AI29: =Hedge_Total!G259 | AJ29: =IF(B29>$K$18,-1*$J$18,(($K$18-B29)*$I$18)-$J$18) | AK29: =Hedge_Total!G289 | AL29: =IF(B29>$K$19,-1*$J$19,(($K$19-B29)*$I$19)-$J$19) | AM29: =Hedge_Total!G319 | AN29: =IF(B29>$K$20,-1*$J$20,(($K$20-B29)*$I$20)-$J$20) | AO29: =Hedge_Total!G349 | AP29: =IF(B29>$K$21,-1*$J$21,(($K$21-B29)*$I$21)-$J$21) | AQ29: =Hedge_Total!G379 | AR29: =IF(B29>$K$22,-1*$J$22,(($K$22-B29)*$I$22)-$J$22) | AS29: =Hedge_Total!G409 | AT29: =IF(B29>$K$23,-1*$J$23,(($K$23-B29)*$I$23)-$J$23)
B30: =B29-1 | C30: =J30/$C$16 | D30: =K30/$C$16 | E30: =($C$10*B30)-$F$10 | F30: =(E30/$F$10) | H30: =H29-1 | I30: =Hedge_Total!C440 | J30: =Hedge_Total!G440 | K30: =T30+V30+X30+Z30+AB30+AD30+AF30+AH30+AJ30+AL30+AN30+AP30+AR30+AT30 | L30: =N30/$F$10 | M30: =O30/$F$10 | N30: =E30+J30 | O30: =E30+K30 | P30: =J31-2*J30+J29 | R30: =R29-1 | S30: =Hedge_Total!G23 | T30: =IF(B30>$K$10,-1*$J$10,(($K$10-B30)*$I$10)-$J$10) | U30: =Hedge_Total!G52 | V30: =IF(B30>$K$11,-1*$J$11,(($K$11-B30)*$I$11)-$J$11) | W30: =Hedge_Total!G81 | X30: =IF(B30>$K$12,-1*$J$12,(($K$12-B30)*$I$12)-$J$12) | Y30: =Hedge_Total!G110 | Z30: =IF(B30>$K$13,-1*$J$13,(($K$13-B30)*$I$13)-$J$13) | AA30: =Hedge_Total!G140 | AB30: =IF(B30>$K$14,-1*$J$14,(($K$14-B30)*$I$14)-$J$14) | AC30: =Hedge_Total!G170 | AD30: =IF(B30>$K$15,-1*$J$15,(($K$15-B30)*$I$15)-$J$15) | AE30: =Hedge_Total!G200 | AF30: =IF(B30>$K$16,-1*$J$16,(($K$16-B30)*$I$16)-$J$16) | AG30: =Hedge_Total!G230 | AH30: =IF(B30>$K$17,-1*$J$17,(($K$17-B30)*$I$17)-$J$17) | AI30: =Hedge_Total!G260 | AJ30: =IF(B30>$K$18,-1*$J$18,(($K$18-B30)*$I$18)-$J$18) | AK30: =Hedge_Total!G290 | AL30: =IF(B30>$K$19,-1*$J$19,(($K$19-B30)*$I$19)-$J$19) | AM30: =Hedge_Total!G320 | AN30: =IF(B30>$K$20,-1*$J$20,(($K$20-B30)*$I$20)-$J$20) | AO30: =Hedge_Total!G350 | AP30: =IF(B30>$K$21,-1*$J$21,(($K$21-B30)*$I$21)-$J$21) | AQ30: =Hedge_Total!G380 | AR30: =IF(B30>$K$22,-1*$J$22,(($K$22-B30)*$I$22)-$J$22) | AS30: =Hedge_Total!G410 | AT30: =IF(B30>$K$23,-1*$J$23,(($K$23-B30)*$I$23)-$J$23)
B31: =B30-1 | C31: =J31/$C$16 | D31: =K31/$C$16 | E31: =($C$10*B31)-$F$10 | F31: =(E31/$F$10) | H31: =H30-1 | I31: =Hedge_Total!C441 | J31: =Hedge_Total!G441 | K31: =T31+V31+X31+Z31+AB31+AD31+AF31+AH31+AJ31+AL31+AN31+AP31+AR31+AT31 | L31: =N31/$F$10 | M31: =O31/$F$10 | N31: =E31+J31 | O31: =E31+K31 | P31: =J32-2*J31+J30 | R31: =R30-1 | S31: =Hedge_Total!G24 | T31: =IF(B31>$K$10,-1*$J$10,(($K$10-B31)*$I$10)-$J$10) | U31: =Hedge_Total!G53 | V31: =IF(B31>$K$11,-1*$J$11,(($K$11-B31)*$I$11)-$J$11) | W31: =Hedge_Total!G82 | X31: =IF(B31>$K$12,-1*$J$12,(($K$12-B31)*$I$12)-$J$12) | Y31: =Hedge_Total!G111 | Z31: =IF(B31>$K$13,-1*$J$13,(($K$13-B31)*$I$13)-$J$13) | AA31: =Hedge_Total!G141 | AB31: =IF(B31>$K$14,-1*$J$14,(($K$14-B31)*$I$14)-$J$14) | AC31: =Hedge_Total!G171 | AD31: =IF(B31>$K$15,-1*$J$15,(($K$15-B31)*$I$15)-$J$15) | AE31: =Hedge_Total!G201 | AF31: =IF(B31>$K$16,-1*$J$16,(($K$16-B31)*$I$16)-$J$16) | AG31: =Hedge_Total!G231 | AH31: =IF(B31>$K$17,-1*$J$17,(($K$17-B31)*$I$17)-$J$17) | AI31: =Hedge_Total!G261 | AJ31: =IF(B31>$K$18,-1*$J$18,(($K$18-B31)*$I$18)-$J$18) | AK31: =Hedge_Total!G291 | AL31: =IF(B31>$K$19,-1*$J$19,(($K$19-B31)*$I$19)-$J$19) | AM31: =Hedge_Total!G321 | AN31: =IF(B31>$K$20,-1*$J$20,(($K$20-B31)*$I$20)-$J$20) | AO31: =Hedge_Total!G351 | AP31: =IF(B31>$K$21,-1*$J$21,(($K$21-B31)*$I$21)-$J$21) | AQ31: =Hedge_Total!G381 | AR31: =IF(B31>$K$22,-1*$J$22,(($K$22-B31)*$I$22)-$J$22) | AS31: =Hedge_Total!G411 | AT31: =IF(B31>$K$23,-1*$J$23,(($K$23-B31)*$I$23)-$J$23)
B32: =B31-1 | C32: =J32/$C$16 | D32: =K32/$C$16 | E32: =($C$10*B32)-$F$10 | F32: =(E32/$F$10) | H32: =H31-1 | I32: =Hedge_Total!C442 | J32: =Hedge_Total!G442 | K32: =T32+V32+X32+Z32+AB32+AD32+AF32+AH32+AJ32+AL32+AN32+AP32+AR32+AT32 | L32: =N32/$F$10 | M32: =O32/$F$10 | N32: =E32+J32 | O32: =E32+K32 | P32: =J33-2*J32+J31 | R32: =R31-1 | S32: =Hedge_Total!G25 | T32: =IF(B32>$K$10,-1*$J$10,(($K$10-B32)*$I$10)-$J$10) | U32: =Hedge_Total!G54 | V32: =IF(B32>$K$11,-1*$J$11,(($K$11-B32)*$I$11)-$J$11) | W32: =Hedge_Total!G83 | X32: =IF(B32>$K$12,-1*$J$12,(($K$12-B32)*$I$12)-$J$12) | Y32: =Hedge_Total!G112 | Z32: =IF(B32>$K$13,-1*$J$13,(($K$13-B32)*$I$13)-$J$13) | AA32: =Hedge_Total!G142 | AB32: =IF(B32>$K$14,-1*$J$14,(($K$14-B32)*$I$14)-$J$14) | AC32: =Hedge_Total!G172 | AD32: =IF(B32>$K$15,-1*$J$15,(($K$15-B32)*$I$15)-$J$15) | AE32: =Hedge_Total!G202 | AF32: =IF(B32>$K$16,-1*$J$16,(($K$16-B32)*$I$16)-$J$16) | AG32: =Hedge_Total!G232 | AH32: =IF(B32>$K$17,-1*$J$17,(($K$17-B32)*$I$17)-$J$17) | AI32: =Hedge_Total!G262 | AJ32: =IF(B32>$K$18,-1*$J$18,(($K$18-B32)*$I$18)-$J$18) | AK32: =Hedge_Total!G292 | AL32: =IF(B32>$K$19,-1*$J$19,(($K$19-B32)*$I$19)-$J$19) | AM32: =Hedge_Total!G322 | AN32: =IF(B32>$K$20,-1*$J$20,(($K$20-B32)*$I$20)-$J$20) | AO32: =Hedge_Total!G352 | AP32: =IF(B32>$K$21,-1*$J$21,(($K$21-B32)*$I$21)-$J$21) | AQ32: =Hedge_Total!G382 | AR32: =IF(B32>$K$22,-1*$J$22,(($K$22-B32)*$I$22)-$J$22) | AS32: =Hedge_Total!G412 | AT32: =IF(B32>$K$23,-1*$J$23,(($K$23-B32)*$I$23)-$J$23)
B33: =B32-1 | C33: =J33/$C$16 | D33: =K33/$C$16 | E33: =($C$10*B33)-$F$10 | F33: =(E33/$F$10) | H33: =H32-1 | I33: =Hedge_Total!C443 | J33: =Hedge_Total!G443 | K33: =T33+V33+X33+Z33+AB33+AD33+AF33+AH33+AJ33+AL33+AN33+AP33+AR33+AT33 | L33: =N33/$F$10 | M33: =O33/$F$10 | N33: =E33+J33 | O33: =E33+K33 | P33: =J34-2*J33+J32 | R33: =R32-1 | S33: =Hedge_Total!G26 | T33: =IF(B33>$K$10,-1*$J$10,(($K$10-B33)*$I$10)-$J$10) | U33: =Hedge_Total!G55 | V33: =IF(B33>$K$11,-1*$J$11,(($K$11-B33)*$I$11)-$J$11) | W33: =Hedge_Total!G84 | X33: =IF(B33>$K$12,-1*$J$12,(($K$12-B33)*$I$12)-$J$12) | Y33: =Hedge_Total!G113 | Z33: =IF(B33>$K$13,-1*$J$13,(($K$13-B33)*$I$13)-$J$13) | AA33: =Hedge_Total!G143 | AB33: =IF(B33>$K$14,-1*$J$14,(($K$14-B33)*$I$14)-$J$14) | AC33: =Hedge_Total!G173 | AD33: =IF(B33>$K$15,-1*$J$15,(($K$15-B33)*$I$15)-$J$15) | AE33: =Hedge_Total!G203 | AF33: =IF(B33>$K$16,-1*$J$16,(($K$16-B33)*$I$16)-$J$16) | AG33: =Hedge_Total!G233 | AH33: =IF(B33>$K$17,-1*$J$17,(($K$17-B33)*$I$17)-$J$17) | AI33: =Hedge_Total!G263 | AJ33: =IF(B33>$K$18,-1*$J$18,(($K$18-B33)*$I$18)-$J$18) | AK33: =Hedge_Total!G293 | AL33: =IF(B33>$K$19,-1*$J$19,(($K$19-B33)*$I$19)-$J$19) | AM33: =Hedge_Total!G323 | AN33: =IF(B33>$K$20,-1*$J$20,(($K$20-B33)*$I$20)-$J$20) | AO33: =Hedge_Total!G353 | AP33: =IF(B33>$K$21,-1*$J$21,(($K$21-B33)*$I$21)-$J$21) | AQ33: =Hedge_Total!G383 | AR33: =IF(B33>$K$22,-1*$J$22,(($K$22-B33)*$I$22)-$J$22) | AS33: =Hedge_Total!G413 | AT33: =IF(B33>$K$23,-1*$J$23,(($K$23-B33)*$I$23)-$J$23)
B34: =B33-1 | C34: =J34/$C$16 | D34: =K34/$C$16 | E34: =($C$10*B34)-$F$10 | F34: =(E34/$F$10) | H34: =H33-1 | I34: =Hedge_Total!C444 | J34: =Hedge_Total!G444 | K34: =T34+V34+X34+Z34+AB34+AD34+AF34+AH34+AJ34+AL34+AN34+AP34+AR34+AT34 | L34: =N34/$F$10 | M34: =O34/$F$10 | N34: =E34+J34 | O34: =E34+K34 | P34: =J35-2*J34+J33 | R34: =R33-1 | S34: =Hedge_Total!G27 | T34: =IF(B34>$K$10,-1*$J$10,(($K$10-B34)*$I$10)-$J$10) | U34: =Hedge_Total!G56 | V34: =IF(B34>$K$11,-1*$J$11,(($K$11-B34)*$I$11)-$J$11) | W34: =Hedge_Total!G85 | X34: =IF(B34>$K$12,-1*$J$12,(($K$12-B34)*$I$12)-$J$12) | Y34: =Hedge_Total!G114 | Z34: =IF(B34>$K$13,-1*$J$13,(($K$13-B34)*$I$13)-$J$13) | AA34: =Hedge_Total!G144 | AB34: =IF(B34>$K$14,-1*$J$14,(($K$14-B34)*$I$14)-$J$14) | AC34: =Hedge_Total!G174 | AD34: =IF(B34>$K$15,-1*$J$15,(($K$15-B34)*$I$15)-$J$15) | AE34: =Hedge_Total!G204 | AF34: =IF(B34>$K$16,-1*$J$16,(($K$16-B34)*$I$16)-$J$16) | AG34: =Hedge_Total!G234 | AH34: =IF(B34>$K$17,-1*$J$17,(($K$17-B34)*$I$17)-$J$17) | AI34: =Hedge_Total!G264 | AJ34: =IF(B34>$K$18,-1*$J$18,(($K$18-B34)*$I$18)-$J$18) | AK34: =Hedge_Total!G294 | AL34: =IF(B34>$K$19,-1*$J$19,(($K$19-B34)*$I$19)-$J$19) | AM34: =Hedge_Total!G324 | AN34: =IF(B34>$K$20,-1*$J$20,(($K$20-B34)*$I$20)-$J$20) | AO34: =Hedge_Total!G354 | AP34: =IF(B34>$K$21,-1*$J$21,(($K$21-B34)*$I$21)-$J$21) | AQ34: =Hedge_Total!G384 | AR34: =IF(B34>$K$22,-1*$J$22,(($K$22-B34)*$I$22)-$J$22) | AS34: =Hedge_Total!G414 | AT34: =IF(B34>$K$23,-1*$J$23,(($K$23-B34)*$I$23)-$J$23)
B35: =B34-1 | C35: =J35/$C$16 | D35: =K35/$C$16 | E35: =($C$10*B35)-$F$10 | F35: =(E35/$F$10) | H35: =H34-1 | I35: =Hedge_Total!C445 | J35: =Hedge_Total!G445 | K35: =T35+V35+X35+Z35+AB35+AD35+AF35+AH35+AJ35+AL35+AN35+AP35+AR35+AT35 | L35: =N35/$F$10 | M35: =O35/$F$10 | N35: =E35+J35 | O35: =E35+K35 | P35: =J36-2*J35+J34 | R35: =R34-1 | S35: =Hedge_Total!G28 | T35: =IF(B35>$K$10,-1*$J$10,(($K$10-B35)*$I$10)-$J$10) | U35: =Hedge_Total!G57 | V35: =IF(B35>$K$11,-1*$J$11,(($K$11-B35)*$I$11)-$J$11) | W35: =Hedge_Total!G86 | X35: =IF(B35>$K$12,-1*$J$12,(($K$12-B35)*$I$12)-$J$12) | Y35: =Hedge_Total!G115 | Z35: =IF(B35>$K$13,-1*$J$13,(($K$13-B35)*$I$13)-$J$13) | AA35: =Hedge_Total!G145 | AB35: =IF(B35>$K$14,-1*$J$14,(($K$14-B35)*$I$14)-$J$14) | AC35: =Hedge_Total!G175 | AD35: =IF(B35>$K$15,-1*$J$15,(($K$15-B35)*$I$15)-$J$15) | AE35: =Hedge_Total!G205 | AF35: =IF(B35>$K$16,-1*$J$16,(($K$16-B35)*$I$16)-$J$16) | AG35: =Hedge_Total!G235 | AH35: =IF(B35>$K$17,-1*$J$17,(($K$17-B35)*$I$17)-$J$17) | AI35: =Hedge_Total!G265 | AJ35: =IF(B35>$K$18,-1*$J$18,(($K$18-B35)*$I$18)-$J$18) | AK35: =Hedge_Total!G295 | AL35: =IF(B35>$K$19,-1*$J$19,(($K$19-B35)*$I$19)-$J$19) | AM35: =Hedge_Total!G325 | AN35: =IF(B35>$K$20,-1*$J$20,(($K$20-B35)*$I$20)-$J$20) | AO35: =Hedge_Total!G355 | AP35: =IF(B35>$K$21,-1*$J$21,(($K$21-B35)*$I$21)-$J$21) | AQ35: =Hedge_Total!G385 | AR35: =IF(B35>$K$22,-1*$J$22,(($K$22-B35)*$I$22)-$J$22) | AS35: =Hedge_Total!G415 | AT35: =IF(B35>$K$23,-1*$J$23,(($K$23-B35)*$I$23)-$J$23)
B36: =B35-1 | C36: =J36/$C$16 | D36: =K36/$C$16 | E36: =($C$10*B36)-$F$10 | F36: =(E36/$F$10) | H36: =H35-1 | I36: =Hedge_Total!C446 | J36: =Hedge_Total!G446 | K36: =T36+V36+X36+Z36+AB36+AD36+AF36+AH36+AJ36+AL36+AN36+AP36+AR36+AT36 | L36: =N36/$F$10 | M36: =O36/$F$10 | N36: =E36+J36 | O36: =E36+K36 | P36: =J37-2*J36+J35 | R36: =R35-1 | S36: =Hedge_Total!G29 | T36: =IF(B36>$K$10,-1*$J$10,(($K$10-B36)*$I$10)-$J$10) | U36: =Hedge_Total!G58 | V36: =IF(B36>$K$11,-1*$J$11,(($K$11-B36)*$I$11)-$J$11) | W36: =Hedge_Total!G87 | X36: =IF(B36>$K$12,-1*$J$12,(($K$12-B36)*$I$12)-$J$12) | Y36: =Hedge_Total!G116 | Z36: =IF(B36>$K$13,-1*$J$13,(($K$13-B36)*$I$13)-$J$13) | AA36: =Hedge_Total!G146 | AB36: =IF(B36>$K$14,-1*$J$14,(($K$14-B36)*$I$14)-$J$14) | AC36: =Hedge_Total!G176 | AD36: =IF(B36>$K$15,-1*$J$15,(($K$15-B36)*$I$15)-$J$15) | AE36: =Hedge_Total!G206 | AF36: =IF(B36>$K$16,-1*$J$16,(($K$16-B36)*$I$16)-$J$16) | AG36: =Hedge_Total!G236 | AH36: =IF(B36>$K$17,-1*$J$17,(($K$17-B36)*$I$17)-$J$17) | AI36: =Hedge_Total!G266 | AJ36: =IF(B36>$K$18,-1*$J$18,(($K$18-B36)*$I$18)-$J$18) | AK36: =Hedge_Total!G296 | AL36: =IF(B36>$K$19,-1*$J$19,(($K$19-B36)*$I$19)-$J$19) | AM36: =Hedge_Total!G326 | AN36: =IF(B36>$K$20,-1*$J$20,(($K$20-B36)*$I$20)-$J$20) | AO36: =Hedge_Total!G356 | AP36: =IF(B36>$K$21,-1*$J$21,(($K$21-B36)*$I$21)-$J$21) | AQ36: =Hedge_Total!G386 | AR36: =IF(B36>$K$22,-1*$J$22,(($K$22-B36)*$I$22)-$J$22) | AS36: =Hedge_Total!G416 | AT36: =IF(B36>$K$23,-1*$J$23,(($K$23-B36)*$I$23)-$J$23)
B37: =B36-1 | C37: =J37/$C$16 | D37: =K37/$C$16 | E37: =($C$10*B37)-$F$10 | F37: =(E37/$F$10) | H37: =H36-1 | I37: =Hedge_Total!C447 | J37: =Hedge_Total!G447 | K37: =T37+V37+X37+Z37+AB37+AD37+AF37+AH37+AJ37+AL37+AN37+AP37+AR37+AT37 | L37: =N37/$F$10 | M37: =O37/$F$10 | N37: =E37+J37 | O37: =E37+K37 | P37: =J38-2*J37+J36 | R37: =R36-1 | S37: =Hedge_Total!G30 | T37: =IF(B37>$K$10,-1*$J$10,(($K$10-B37)*$I$10)-$J$10) | U37: =Hedge_Total!G59 | V37: =IF(B37>$K$11,-1*$J$11,(($K$11-B37)*$I$11)-$J$11) | W37: =Hedge_Total!G88 | X37: =IF(B37>$K$12,-1*$J$12,(($K$12-B37)*$I$12)-$J$12) | Y37: =Hedge_Total!G117 | Z37: =IF(B37>$K$13,-1*$J$13,(($K$13-B37)*$I$13)-$J$13) | AA37: =Hedge_Total!G147 | AB37: =IF(B37>$K$14,-1*$J$14,(($K$14-B37)*$I$14)-$J$14) | AC37: =Hedge_Total!G177 | AD37: =IF(B37>$K$15,-1*$J$15,(($K$15-B37)*$I$15)-$J$15) | AE37: =Hedge_Total!G207 | AF37: =IF(B37>$K$16,-1*$J$16,(($K$16-B37)*$I$16)-$J$16) | AG37: =Hedge_Total!G237 | AH37: =IF(B37>$K$17,-1*$J$17,(($K$17-B37)*$I$17)-$J$17) | AI37: =Hedge_Total!G267 | AJ37: =IF(B37>$K$18,-1*$J$18,(($K$18-B37)*$I$18)-$J$18) | AK37: =Hedge_Total!G297 | AL37: =IF(B37>$K$19,-1*$J$19,(($K$19-B37)*$I$19)-$J$19) | AM37: =Hedge_Total!G327 | AN37: =IF(B37>$K$20,-1*$J$20,(($K$20-B37)*$I$20)-$J$20) | AO37: =Hedge_Total!G357 | AP37: =IF(B37>$K$21,-1*$J$21,(($K$21-B37)*$I$21)-$J$21) | AQ37: =Hedge_Total!G387 | AR37: =IF(B37>$K$22,-1*$J$22,(($K$22-B37)*$I$22)-$J$22) | AS37: =Hedge_Total!G417 | AT37: =IF(B37>$K$23,-1*$J$23,(($K$23-B37)*$I$23)-$J$23)
B38: =B37-1 | C38: =J38/$C$16 | D38: =K38/$C$16 | E38: =($C$10*B38)-$F$10 | F38: =(E38/$F$10) | H38: =H37-1 | I38: =Hedge_Total!C448 | J38: =Hedge_Total!G448 | K38: =T38+V38+X38+Z38+AB38+AD38+AF38+AH38+AJ38+AL38+AN38+AP38+AR38+AT38 | L38: =N38/$F$10 | M38: =O38/$F$10 | N38: =E38+J38 | O38: =E38+K38 | P38: =J39-2*J38+J37 | R38: =R37-1 | S38: =Hedge_Total!G31 | T38: =IF(B38>$K$10,-1*$J$10,(($K$10-B38)*$I$10)-$J$10) | U38: =Hedge_Total!G60 | V38: =IF(B38>$K$11,-1*$J$11,(($K$11-B38)*$I$11)-$J$11) | W38: =Hedge_Total!G89 | X38: =IF(B38>$K$12,-1*$J$12,(($K$12-B38)*$I$12)-$J$12) | Y38: =Hedge_Total!G118 | Z38: =IF(B38>$K$13,-1*$J$13,(($K$13-B38)*$I$13)-$J$13) | AA38: =Hedge_Total!G148 | AB38: =IF(B38>$K$14,-1*$J$14,(($K$14-B38)*$I$14)-$J$14) | AC38: =Hedge_Total!G178 | AD38: =IF(B38>$K$15,-1*$J$15,(($K$15-B38)*$I$15)-$J$15) | AE38: =Hedge_Total!G208 | AF38: =IF(B38>$K$16,-1*$J$16,(($K$16-B38)*$I$16)-$J$16) | AG38: =Hedge_Total!G238 | AH38: =IF(B38>$K$17,-1*$J$17,(($K$17-B38)*$I$17)-$J$17) | AI38: =Hedge_Total!G268 | AJ38: =IF(B38>$K$18,-1*$J$18,(($K$18-B38)*$I$18)-$J$18) | AK38: =Hedge_Total!G298 | AL38: =IF(B38>$K$19,-1*$J$19,(($K$19-B38)*$I$19)-$J$19) | AM38: =Hedge_Total!G328 | AN38: =IF(B38>$K$20,-1*$J$20,(($K$20-B38)*$I$20)-$J$20) | AO38: =Hedge_Total!G358 | AP38: =IF(B38>$K$21,-1*$J$21,(($K$21-B38)*$I$21)-$J$21) | AQ38: =Hedge_Total!G388 | AR38: =IF(B38>$K$22,-1*$J$22,(($K$22-B38)*$I$22)-$J$22) | AS38: =Hedge_Total!G418 | AT38: =IF(B38>$K$23,-1*$J$23,(($K$23-B38)*$I$23)-$J$23)
B39: =B38-1 | C39: =J39/$C$16 | D39: =K39/$C$16 | E39: =($C$10*B39)-$F$10 | F39: =(E39/$F$10) | H39: =H38-1 | I39: =Hedge_Total!C449 | J39: =Hedge_Total!G449 | K39: =T39+V39+X39+Z39+AB39+AD39+AF39+AH39+AJ39+AL39+AN39+AP39+AR39+AT39 | L39: =N39/$F$10 | M39: =O39/$F$10 | N39: =E39+J39 | O39: =E39+K39 | P39: =J40-2*J39+J38 | R39: =R38-1 | S39: =Hedge_Total!G32 | T39: =IF(B39>$K$10,-1*$J$10,(($K$10-B39)*$I$10)-$J$10) | U39: =Hedge_Total!G61 | V39: =IF(B39>$K$11,-1*$J$11,(($K$11-B39)*$I$11)-$J$11) | W39: =Hedge_Total!G90 | X39: =IF(B39>$K$12,-1*$J$12,(($K$12-B39)*$I$12)-$J$12) | Y39: =Hedge_Total!G119 | Z39: =IF(B39>$K$13,-1*$J$13,(($K$13-B39)*$I$13)-$J$13) | AA39: =Hedge_Total!G149 | AB39: =IF(B39>$K$14,-1*$J$14,(($K$14-B39)*$I$14)-$J$14) | AC39: =Hedge_Total!G179 | AD39: =IF(B39>$K$15,-1*$J$15,(($K$15-B39)*$I$15)-$J$15) | AE39: =Hedge_Total!G209 | AF39: =IF(B39>$K$16,-1*$J$16,(($K$16-B39)*$I$16)-$J$16) | AG39: =Hedge_Total!G239 | AH39: =IF(B39>$K$17,-1*$J$17,(($K$17-B39)*$I$17)-$J$17) | AI39: =Hedge_Total!G269 | AJ39: =IF(B39>$K$18,-1*$J$18,(($K$18-B39)*$I$18)-$J$18) | AK39: =Hedge_Total!G299 | AL39: =IF(B39>$K$19,-1*$J$19,(($K$19-B39)*$I$19)-$J$19) | AM39: =Hedge_Total!G329 | AN39: =IF(B39>$K$20,-1*$J$20,(($K$20-B39)*$I$20)-$J$20) | AO39: =Hedge_Total!G359 | AP39: =IF(B39>$K$21,-1*$J$21,(($K$21-B39)*$I$21)-$J$21) | AQ39: =Hedge_Total!G389 | AR39: =IF(B39>$K$22,-1*$J$22,(($K$22-B39)*$I$22)-$J$22) | AS39: =Hedge_Total!G419 | AT39: =IF(B39>$K$23,-1*$J$23,(($K$23-B39)*$I$23)-$J$23)
B40: =B39-1 | C40: =J40/$C$16 | D40: =K40/$C$16 | E40: =($C$10*B40)-$F$10 | F40: =(E40/$F$10) | H40: =H39-1 | I40: =Hedge_Total!C450 | J40: =Hedge_Total!G450 | K40: =T40+V40+X40+Z40+AB40+AD40+AF40+AH40+AJ40+AL40+AN40+AP40+AR40+AT40 | L40: =N40/$F$10 | M40: =O40/$F$10 | N40: =E40+J40 | O40: =E40+K40 | P40: =J41-2*J40+J39 | R40: =R39-1 | S40: =Hedge_Total!G33 | T40: =IF(B40>$K$10,-1*$J$10,(($K$10-B40)*$I$10)-$J$10) | U40: =Hedge_Total!G62 | V40: =IF(B40>$K$11,-1*$J$11,(($K$11-B40)*$I$11)-$J$11) | W40: =Hedge_Total!G91 | X40: =IF(B40>$K$12,-1*$J$12,(($K$12-B40)*$I$12)-$J$12) | Y40: =Hedge_Total!G120 | Z40: =IF(B40>$K$13,-1*$J$13,(($K$13-B40)*$I$13)-$J$13) | AA40: =Hedge_Total!G150 | AB40: =IF(B40>$K$14,-1*$J$14,(($K$14-B40)*$I$14)-$J$14) | AC40: =Hedge_Total!G180 | AD40: =IF(B40>$K$15,-1*$J$15,(($K$15-B40)*$I$15)-$J$15) | AE40: =Hedge_Total!G210 | AF40: =IF(B40>$K$16,-1*$J$16,(($K$16-B40)*$I$16)-$J$16) | AG40: =Hedge_Total!G240 | AH40: =IF(B40>$K$17,-1*$J$17,(($K$17-B40)*$I$17)-$J$17) | AI40: =Hedge_Total!G270 | AJ40: =IF(B40>$K$18,-1*$J$18,(($K$18-B40)*$I$18)-$J$18) | AK40: =Hedge_Total!G300 | AL40: =IF(B40>$K$19,-1*$J$19,(($K$19-B40)*$I$19)-$J$19) | AM40: =Hedge_Total!G330 | AN40: =IF(B40>$K$20,-1*$J$20,(($K$20-B40)*$I$20)-$J$20) | AO40: =Hedge_Total!G360 | AP40: =IF(B40>$K$21,-1*$J$21,(($K$21-B40)*$I$21)-$J$21) | AQ40: =Hedge_Total!G390 | AR40: =IF(B40>$K$22,-1*$J$22,(($K$22-B40)*$I$22)-$J$22) | AS40: =Hedge_Total!G420 | AT40: =IF(B40>$K$23,-1*$J$23,(($K$23-B40)*$I$23)-$J$23)
... B53: =B52-1 | C53: =J53/$C$16 | D53: =K53/$C$16 | E53: =($C$10*B53)-$F$10 | F53: =(E53/$F$10) | H53: =H52-1 | I53: =Hedge_Total!C463 | J53: =Hedge_Total!G463 | K53: =T53+V53+X53+Z53+AB53+AD53+AF53+AH53+AJ53+AL53+AN53+AP53+AR53+AT53 | L53: =N53/$F$10 | M53: =O53/$F$10 | N53: =E53+J53 | O53: =E53+K53 | P53: =J54-2*J53+J52 | R53: =R52-1 | S53: =Hedge_Total!G46 | T53: =IF(B53>$K$10,-1*$J$10,(($K$10-B53)*$I$10)-$J$10) | U53: =Hedge_Total!G75 | V53: =IF(B53>$K$11,-1*$J$11,(($K$11-B53)*$I$11)-$J$11) | W53: =Hedge_Total!G104 | X53: =IF(B53>$K$12,-1*$J$12,(($K$12-B53)*$I$12)-$J$12) | Y53: =Hedge_Total!G133 | Z53: =IF(B53>$K$13,-1*$J$13,(($K$13-B53)*$I$13)-$J$13) | AA53: =Hedge_Total!G163 | AB53: =IF(B53>$K$14,-1*$J$14,(($K$14-B53)*$I$14)-$J$14) | AC53: =Hedge_Total!G193 | AD53: =IF(B53>$K$15,-1*$J$15,(($K$15-B53)*$I$15)-$J$15) | AE53: =Hedge_Total!G223 | AF53: =IF(B53>$K$16,-1*$J$16,(($K$16-B53)*$I$16)-$J$16) | AG53: =Hedge_Total!G253 | AH53: =IF(B53>$K$17,-1*$J$17,(($K$17-B53)*$I$17)-$J$17) | AI53: =Hedge_Total!G283 | AJ53: =IF(B53>$K$18,-1*$J$18,(($K$18-B53)*$I$18)-$J$18) | AK53: =Hedge_Total!G313 | AL53: =IF(B53>$K$19,-1*$J$19,(($K$19-B53)*$I$19)-$J$19) | AM53: =Hedge_Total!G343 | AN53: =IF(B53>$K$20,-1*$J$20,(($K$20-B53)*$I$20)-$J$20) | AO53: =Hedge_Total!G373 | AP53: =IF(B53>$K$21,-1*$J$21,(($K$21-B53)*$I$21)-$J$21) | AQ53: =Hedge_Total!G403 | AR53: =IF(B53>$K$22,-1*$J$22,(($K$22-B53)*$I$22)-$J$22) | AS53: =Hedge_Total!G433 | AT53: =IF(B53>$K$23,-1*$J$23,(($K$23-B53)*$I$23)-$J$23)
B54: =B53-1 | C54: =J54/$C$16 | D54: =K54/$C$16 | E54: =($C$10*B54)-$F$10 | F54: =(E54/$F$10) | H54: =H53-1 | I54: =Hedge_Total!C464 | J54: =Hedge_Total!G464 | K54: =T54+V54+X54+Z54+AB54+AD54+AF54+AH54+AJ54+AL54+AN54+AP54+AR54+AT54 | L54: =N54/$F$10 | M54: =O54/$F$10 | N54: =E54+J54 | O54: =E54+K54 | R54: =R53-1 | S54: =Hedge_Total!G47 | T54: =IF(B54>$K$10,-1*$J$10,(($K$10-B54)*$I$10)-$J$10) | U54: =Hedge_Total!G76 | V54: =IF(B54>$K$11,-1*$J$11,(($K$11-B54)*$I$11)-$J$11) | W54: =Hedge_Total!G105 | X54: =IF(B54>$K$12,-1*$J$12,(($K$12-B54)*$I$12)-$J$12) | Y54: =Hedge_Total!G134 | Z54: =IF(B54>$K$13,-1*$J$13,(($K$13-B54)*$I$13)-$J$13) | AA54: =Hedge_Total!G164 | AB54: =IF(B54>$K$14,-1*$J$14,(($K$14-B54)*$I$14)-$J$14) | AC54: =Hedge_Total!G194 | AD54: =IF(B54>$K$15,-1*$J$15,(($K$15-B54)*$I$15)-$J$15) | AE54: =Hedge_Total!G224 | AF54: =IF(B54>$K$16,-1*$J$16,(($K$16-B54)*$I$16)-$J$16) | AG54: =Hedge_Total!G254 | AH54: =IF(B54>$K$17,-1*$J$17,(($K$17-B54)*$I$17)-$J$17) | AI54: =Hedge_Total!G284 | AJ54: =IF(B54>$K$18,-1*$J$18,(($K$18-B54)*$I$18)-$J$18) | AK54: =Hedge_Total!G314 | AL54: =IF(B54>$K$19,-1*$J$19,(($K$19-B54)*$I$19)-$J$19) | AM54: =Hedge_Total!G344 | AN54: =IF(B54>$K$20,-1*$J$20,(($K$20-B54)*$I$20)-$J$20) | AO54: =Hedge_Total!G374 | AP54: =IF(B54>$K$21,-1*$J$21,(($K$21-B54)*$I$21)-$J$21) | AQ54: =Hedge_Total!G404 | AR54: =IF(B54>$K$22,-1*$J$22,(($K$22-B54)*$I$22)-$J$22) | AS54: =Hedge_Total!G434 | AT54: =IF(B54>$K$23,-1*$J$23,(($K$23-B54)*$I$23)-$J$23)

Sheet Hedge_Far
A1: symbol | B1: strike | C1: delta | D1: gamma | E1: vega | F1: theta | G1: mark_price | H1: iv | I1: dte | J1: T | K1: type | L1: spot_price | M1: hedge_cost_per_day | N1: total_price | O1: position | P1: contracts | R1: Start | S1: Current
A2: =Far_laeyr!B20 | B2: =VLOOKUP(A2,OptionBoard!$A$2:$M$86,2,FALSE()) | C2: =VLOOKUP(A2,OptionBoard!$A$2:$M$86,3,0) | D2: =VLOOKUP(A2,OptionBoard!$A$2:$M$86,4,0) | E2: =VLOOKUP(A2,OptionBoard!$A$2:$M$86,5,0) | F2: =VLOOKUP(A2,OptionBoard!$A$2:$M$86,6,0) | G2: =VLOOKUP(A2,Far_laeyr!$B$9:$H$16,7,0) | H2: =VLOOKUP(A2,OptionBoard!$A$2:$M$86,8,0) | I2: =VLOOKUP(A2,OptionBoard!$A$2:$M$86,9,0) | J2: =VLOOKUP(A2,OptionBoard!$A$2:$M$86,10,0) | K2: =VLOOKUP(A2,OptionBoard!$A$2:$M$86,11,FALSE()) | L2: =VLOOKUP(A2,OptionBoard!$A$2:$M$86,12,0) | M2: =VLOOKUP(A2,OptionBoard!$A$2:$M$86,13,0) | N2: =G2*P2 | O2: buy | P2: =Far_laeyr!G20 | R2: =G2 | S2: =VLOOKUP(A2,OptionBoard!$A$2:$G$93,7,FALSE()) | U2: =R2-S2
A3: =Far_laeyr!B21 | B3: =VLOOKUP(A3,OptionBoard!$A$2:$M$86,2,FALSE()) | C3: =VLOOKUP(A3,OptionBoard!$A$2:$M$86,3,0) | D3: =VLOOKUP(A3,OptionBoard!$A$2:$M$86,4,0) | E3: =VLOOKUP(A3,OptionBoard!$A$2:$M$86,5,0) | F3: =VLOOKUP(A3,OptionBoard!$A$2:$M$86,6,0) | G3: =VLOOKUP(A3,Far_laeyr!$B$9:$H$16,7,0) | H3: =VLOOKUP(A3,OptionBoard!$A$2:$M$86,8,0) | I3: =VLOOKUP(A3,OptionBoard!$A$2:$M$86,9,0) | J3: =VLOOKUP(A3,OptionBoard!$A$2:$M$86,10,0) | K3: =VLOOKUP(A3,OptionBoard!$A$2:$M$86,11,FALSE()) | L3: =VLOOKUP(A3,OptionBoard!$A$2:$M$86,12,0) | M3: =VLOOKUP(A3,OptionBoard!$A$2:$M$86,13,0) | N3: =G3*P3 | O3: buy | P3: =Far_laeyr!G21 | R3: =G3 | S3: =VLOOKUP(A3,OptionBoard!$A$2:$G$93,7,FALSE()) | U3: =R3-S3
